Workbook

Sheet QUADRO DE CARGA
A1: QUADRO DE CARGAS
A2: LOCAL: | AP2: CÁLCULOS DAS POTÊNCIAS | AS2: QUEDA DE TENSÃO | AY2: FATORES DE CORREÇÃO POR AGRUPAMENTO | BB2: FATORES DE CORREÇÃO POR TEMPERATURA | BH2: CAPACIDADE DO QUADRO (W): | BP2: =IF(BI105="","",381*BI105*0.8) -> #N/A
A3: CIRCUITOS | B3: ILUMINAÇÃO (W) | L3: TOMADAS (W) | V3: AR COND. (W) | AF3: QUADROS (VA) | AP3: TOTAL (W) | AQ3: FATOR DE POTÊNCIA | AR3: TOTAL (VA) | AU3: MÉTODO DE INSTALAÇÃO | AV3: TIPO DE ISOLANTE (PVC OU EPR,XLPE) | AW3: TENSÃO DE ISOLAÇÃO (kV) | AX3: FATOR DE DEMANDA (POR CIRCUITO) | AY3: FORMA DE AGRUPAMENTO DOS CONDUTORES | AZ3: NÚMERO DE CIRCUITOS NO MESMO ELETRODUTO OU BANDEJA | BA3: FATOR DE AGRUPAMENTO | BB3: TIPO DE LINHA | BC3: TEMPERATURA AMBIENTE (°C) | BD3: FATOR DE CORREÇÃO PARA TEMPERATURA AMBIENTE | BE3: TENSÃO (V) | BF3: CORRENTE (A) | BG3: CORRENTE CORRIGIDA (A) | BH3: DISJUNTOR | BJ3: FASES | BM3: EQUILÍBRIO DE FASES | BP3: SEÇÃO SOBRECORRENTE (mm²) | BQ3: SEÇÃO QUEDA DE TENSÃO (mm²) | BR3: SEÇÃO POR CIRCUITO (mm²) | BS3: S | BT3: DESCRIÇÃO DO CIRCUITO
AO4: 10000 | AS4: QUEDA ADMISSÍVEL (%) | AT4: COMPRIMENTO (m) | BH4: POLOS | BI4: (A) | BJ4: A | BK4: B | BL4: C | BM4: A | BN4: B | BO4: C | BU4: Seção por queda de tensão - apoio
A5: 1 | AO5: 1 | AP5: =IF(SUMPRODUCT(B5:AO5, $B$4:$AO$4)=0, "", SUMPRODUCT(B5:AO5, B$4:AO$4)) -> 10000 | AQ5: =IF(AP5="","",IF((SUM(B5:K5)+SUM(AF5:AO5))>=1,1,0.92)) -> 1 | AR5: =IF(AP5="","",ROUND((AP5/AQ5),0)) -> 10000 | AS5: 4 | AT5: 10 | AU5: G - 3VER | AV5: PVC | AW5: 0,6 kV/1 kV | AX5: 1 | AY5: Em feixe: ao ar livre ou sobre superfície; embutidos; em conduto fechado (métodos A a F) | AZ5: 1 | BA5: =INDEX(AGRUPAMENTO!C3:N7,MATCH(AY5,AGRUPAMENTO!B3:B7,0),MATCH(AZ5,AGRUPAMENTO!C2:N2,0)) -> 1 | BB5: NÃO SUBTERRÂNEA | BC5: 30 | BD5: =IF(BB5="SUBTERRÂNEA",IF(AV5="PVC",VLOOKUP(BC5,TEMPERATURA!G2:H16,2,0),VLOOKUP(BC5,TEMPERATURA!G2:I16,3,0)),IF(AV5="PVC",VLOOKUP(BC5,TEMPERATURA!B2:C16,2,0),VLOOKUP(BC5,TEMPERATURA!B2:D16,3,0))) -> 1 | BE5: =IF( AP5="", "", _xlfn.IFS( $BI$111="127/220", IF( BH5=1, 127, IF( BH5=2, ROUND(127*SQRT(3),0), IF( BH5=3, ROUND(127*SQRT(3),0), "" ) ) ), $BI$111="220/380", IF( BH5=1, 220, IF( BH5=2, ROUND(220*SQRT(3),0)-1, IF( BH5=3, ROUND(220*SQRT(3),0)-1, "" ) ) ), $BI$111="254/440", IF( BH5=1, 254, IF( BH5=2, ROUND(254*SQRT(3),0), IF( BH5=3, ROUND(254*SQRT(3),0), "" ) ) ) ) ) -> 127 | BF5: =IF(AP5="","",ROUND(AR5/IF(BH5=1,127,IF(BH5=2,220,IF(BH5=3,381,""))),1)) -> 78.7 | BG5: =(BF5*AX5)/(BD5*BA5) -> 78.7 | BH5: =IF(COUNTA(BJ5:BL5)=0,"",COUNTA(BJ5:BL5)) -> 1 | BI5: =IF(AP5="","", IF(COUNTA(V5:AE5)>=1, MAX(IFERROR(_xlfn.AGGREGATE(15,6,DISJUNTORES!$C$2:$C$100/(DISJUNTORES!$C$2:$C$100>=BG5),1),""),25), IF(COUNTA(L5:U5)>=1, MAX(IFERROR(_xlfn.AGGREGATE(15,6,DISJUNTORES!$C$2:$C$100/(DISJUNTORES!$C$2:$C$100>=BG5),1),""),20), IF(COUNTA(B5:K5)>=1, MAX(IFERROR(_xlfn.AGGREGATE(15,6,DISJUNTORES!$C$2:$C$100/(DISJUNTORES!$C$2:$C$100>=BG5),1),""),16), IFERROR(_xlfn.AGGREGATE(15,6,DISJUNTORES!$C$2:$C$100/(DISJUNTORES!$C$2:$C$100>=BG5),1),""))))) -> 80 | BJ5: x | BM5: =IF(IF(BJ5="","",AR5/COUNTA(BJ5:BL5))=0,"",IF(BJ5="","",AR5/COUNTA(BJ5:BL5))) -> 10000 | BN5: =IF(IF(BK5="","",AR5/COUNTA(BJ5:BL5))=0,"",IF(BK5="","",AR5/COUNTA(BJ5:BL5))) | BO5: =IF(IF(BL5="","",AR5/COUNTA(BJ5:BL5))=0,"",IF(BL5="","",AR5/COUNTA(BJ5:BL5))) | BP5: =INDEX('CAP CONDUÇÃO 70º'!W2:AP25,MATCH(BI5,'CAP CONDUÇÃO 70º'!W2:AP25,1)+1) -> #N/A | BQ5: =IF(AV5="PVC",INDEX('CAP CONDUÇÃO 70º'!A4:A27,MATCH(BU5,'CAP CONDUÇÃO 70º'!A4:A27,1)+1),INDEX('CAP CONDUÇÃO 90º'!A4:A27,MATCH(BU5,'CAP CONDUÇÃO 90º'!A4:A27,1)+1)) -> 6 | BR5: =IF(CONTARVALORES(L5:AO5)>0, MAX(2.5, MAX(BP5:BQ5)), MAX(1.5, MAX(BP5:BQ5))) -> #NAME? | BS5: =IFERROR(IF(BP5="","","3F#"&BR5&"mm²+N"&VLOOKUP($BR$5,NEUTRO!$A:$B,2,0)&"mm²+T"&VLOOKUP($BR$5,TERRA!$A:$B,2,0)&"mm²"),"") | BU5: =_xlfn.IFS( BH5=1, (100*2*AT5*BG5*(1/58))/(AS5*BE5), BH5=2, (100*2*AT5*BG5*(1/58))/(AS5*BE5), BH5=3, (100*SQRT(3)*AT5*BG5*(1/58))/(AS5*BE5) ) -> 5.3421124
A6: 2 | AO6: 2 | AP6: =IF(SUMPRODUCT(B6:AO6, B$4:AO$4)=0, "", SUMPRODUCT(B6:AO6, B$4:AO$4)) -> 20000 | AQ6: =IF(AP6="","",IF((SUM(B6:K6)+SUM(AF6:AO6))>=1,1,0.92)) -> 1 | AR6: =IF(AP6="","",ROUND((AP6/AQ6),0)) -> 20000 | AY6: Em feixe: ao ar livre ou sobre superfície; embutidos; em conduto fechado (métodos A a F) | AZ6: 1 | BA6: =INDEX(AGRUPAMENTO!C4:N8,MATCH(AY6,AGRUPAMENTO!B4:B8,0),MATCH(AZ6,AGRUPAMENTO!C3:N3,0)) -> #N/A | BB6: NÃO SUBTERRÂNEA | BC6: 30 | BD6: =IF(BB6="SUBTERRÂNEA",IF(AV6="PVC",VLOOKUP(BC6,TEMPERATURA!G3:H17,2,0),VLOOKUP(BC6,TEMPERATURA!G3:I17,3,0)),IF(AV6="PVC",VLOOKUP(BC6,TEMPERATURA!B3:C17,2,0),VLOOKUP(BC6,TEMPERATURA!B3:D17,3,0))) -> 1 | BE6: =IF( AP6="", "", _xlfn.IFS( $BI$111="127/220", IF( BH6=1, 127, IF( BH6=2, ROUND(127*SQRT(3),0), IF( BH6=3, ROUND(127*SQRT(3),0), "" ) ) ), $BI$111="220/380", IF( BH6=1, 220, IF( BH6=2, ROUND(220*SQRT(3),0)-1, IF( BH6=3, ROUND(220*SQRT(3),0)-1, "" ) ) ), $BI$111="254/440", IF( BH6=1, 254, IF( BH6=2, ROUND(254*SQRT(3),0), IF( BH6=3, ROUND(254*SQRT(3),0), "" ) ) ) ) ) -> 127 | BF6: =IF(AP6="","",ROUND(AR6/IF(BH6=1,127,IF(BH6=2,220,IF(BH6=3,381,""))),1)) -> 157.5 | BG6: =(BF6*AX6)/(BD6*BA6) -> #N/A | BH6: =IF(COUNTA(BJ6:BL6)=0,"",COUNTA(BJ6:BL6)) -> 1 | BI6: =IF(AP6="","", IF(COUNTA(V6:AE6)>=1, MAX(IFERROR(_xlfn.AGGREGATE(15,6,DISJUNTORES!$C$2:$C$100/(DISJUNTORES!$C$2:$C$100>=BF6),1),""),25), IF(COUNTA(L6:U6)>=1, MAX(IFERROR(_xlfn.AGGREGATE(15,6,DISJUNTORES!$C$2:$C$100/(DISJUNTORES!$C$2:$C$100>=BF6),1),""),20), IF(COUNTA(A6:K6)>=1, MAX(IFERROR(_xlfn.AGGREGATE(15,6,DISJUNTORES!$C$2:$C$100/(DISJUNTORES!$C$2:$C$100>=BF6),1),""),16), IFERROR(_xlfn.AGGREGATE(15,6,DISJUNTORES!$C$2:$C$100/(DISJUNTORES!$C$2:$C$100>=BF6),1),""))))) -> 175 | BJ6: x | BM6: =IF(IF(BJ6="","",AR6/COUNTA(BJ6:BL6))=0,"",IF(BJ6="","",AR6/COUNTA(BJ6:BL6))) -> 20000 | BN6: =IF(IF(BK6="","",AR6/COUNTA(BJ6:BL6))=0,"",IF(BK6="","",AR6/COUNTA(BJ6:BL6))) | BO6: =IF(IF(BL6="","",AR6/COUNTA(BJ6:BL6))=0,"",IF(BL6="","",AR6/COUNTA(BJ6:BL6))) | BP6: {=IFERROR( INDEX( IF(AV6="PVC", 'CAP CONDUÇÃO 70º'!$A:$A, 'CAP CONDUÇÃO 90º'!$A:$A), IF( COUNTIF( IF(AV6="PVC", CHOOSE( MATCH(AU6, {"A1 - 2";"A1 - 3";"A2 - 2";"A2 - 3";"B1 - 2";"B1 - 3";"B2 - 2";"B2 - 3";"C - 2";"C - 3";"D - 2";"D - 3";"E - 2";"E - 3";"F - 2";"F - 3TRI";"F - 3JUST";"G - 3HOR";"G - 3VER"}, 0), 'CAP CONDUÇÃO 70º'!$B:$B, 'CAP CONDUÇÃO 70º'!$C:$C, 'CAP CONDUÇÃO 70º'!$D:$D, 'CAP CONDUÇÃO 70º'!$E:$E, 'CAP CONDUÇÃO 70º'!$F:$F, 'CAP CONDUÇÃO 70º'!$G:$G, 'CAP CONDUÇÃO 70º'!$H:$H, 'CAP CONDUÇÃO 70º'!$I:$I, 'CAP CONDUÇÃO 70º'!$J:$J, 'CAP CONDUÇÃO 70º'!$K:$K, 'CAP CONDUÇÃO 70º'!$L:$L, 'CAP CONDUÇÃO 70º'!$M:$M, 'CAP CONDUÇÃO 70º'!$N:$N, 'CAP CONDUÇÃO 70º'!$O:$O, 'CAP CONDUÇÃO 70º'!$P:$P, 'CAP CONDUÇÃO 70º'!$Q:$Q, 'CAP CONDUÇÃO 70º'!$R:$R, 'CAP CONDUÇÃO 70º'!$S:$S, 'CAP CONDUÇÃO 70º'!$T:$T ), CHOOSE( MATCH(AU6, {"A1 - 2";"A1 - 3";"A2 - 2";"A2 - 3";"B1 - 2";"B1 - 3";"B2 - 2";"B2 - 3";"C - 2";"C - 3";"D - 2";"D - 3";"E - 2";"E - 3";"F - 2";"F - 3TRI";"F - 3JUST";"G - 3HOR";"G - 3VER"}, 0), 'CAP CONDUÇÃO 90º'!$B:$B, 'CAP CONDUÇÃO 90º'!$C:$C, 'CAP CONDUÇÃO 90º'!$D:$D, 'CAP CONDUÇÃO 90º'!$E:$E, 'CAP CONDUÇÃO 90º'!$F:$F, 'CAP CONDUÇÃO 90º'!$G:$G, 'CAP CONDUÇÃO 90º'!$H:$H, 'CAP CONDUÇÃO 90º'!$I:$I, 'CAP CONDUÇÃO 90º'!$J:$J, 'CAP CONDUÇÃO 90º'!$K:$K, 'CAP CONDUÇÃO 90º'!$L:$L, 'CAP CONDUÇÃO 90º'!$M:$M, 'CAP CONDUÇÃO 90º'!$N:$N, 'CAP CONDUÇÃO 90º'!$O:$O, 'CAP CONDUÇÃO 90º'!$P:$P, 'CAP CONDUÇÃO 90º'!$Q:$Q, 'CAP CONDUÇÃO 90º'!$R:$R, 'CAP CONDUÇÃO 90º'!$S:$S, 'CAP CONDUÇÃO 90º'!$T:$T ) ), BI6 ) > 0, MATCH(BI6, IF(AV6="PVC", CHOOSE( MATCH(AU6, {"A1 - 2";"A1 - 3";"A2 - 2";"A2 - 3";"B1 - 2";"B1 - 3";"B2 - 2";"B2 - 3";"C - 2";"C - 3";"D - 2";"D - 3";"E - 2";"E - 3";"F - 2";"F - 3TRI";"F - 3JUST";"G - 3HOR";"G - 3VER"}, 0), 'CAP CONDUÇÃO 70º'!$B:$B, 'CAP CONDUÇÃO 70º'!$C:$C, 'CAP CONDUÇÃO 70º'!$D:$D, 'CAP CONDUÇÃO 70º'!$E:$E, 'CAP CONDUÇÃO 70º'!$F:$F, 'CAP CONDUÇÃO 70º'!$G:$G, 'CAP CONDUÇÃO 70º'!$H:$H, 'CAP CONDUÇÃO 70º'!$I:$I, 'CAP CONDUÇÃO 70º'!$J:$J, 'CAP CONDUÇÃO 70º'!$K:$K, 'CAP CONDUÇÃO 70º'!$L:$L, 'CAP CONDUÇÃO 70º'!$M:$M, 'CAP CONDUÇÃO 70º'!$N:$N, 'CAP CONDUÇÃO 70º'!$O:$O, 'CAP CONDUÇÃO 70º'!$P:$P, 'CAP CONDUÇÃO 70º'!$Q:$Q, 'CAP CONDUÇÃO 70º'!$R:$R, 'CAP CONDUÇÃO 70º'!$S:$S, 'CAP CONDUÇÃO 70º'!$T:$T ), CHOOSE( MATCH(AU6, {"A1 - 2";"A1 - 3";"A2 - 2";"A2 - 3";"B1 - 2";"B1 - 3";"B2 - 2";"B2 - 3";"C - 2";"C - 3";"D - 2";"D - 3";"E - 2";"E - 3";"F - 2";"F - 3TRI";"F - 3JUST";"G - 3HOR";"G - 3VER"}, 0), 'CAP CONDUÇÃO 90º'!$B:$B, 'CAP CONDUÇÃO 90º'!$C:$C, 'CAP CONDUÇÃO 90º'!$D:$D, 'CAP CONDUÇÃO 90º'!$E:$E, 'CAP CONDUÇÃO 90º'!$F:$F, 'CAP CONDUÇÃO 90º'!$G:$G, 'CAP CONDUÇÃO 90º'!$H:$H, 'CAP CONDUÇÃO 90º'!$I:$I, 'CAP CONDUÇÃO 90º'!$J:$J, 'CAP CONDUÇÃO 90º'!$K:$K, 'CAP CONDUÇÃO 90º'!$L:$L, 'CAP CONDUÇÃO 90º'!$M:$M, 'CAP CONDUÇÃO 90º'!$N:$N, 'CAP CONDUÇÃO 90º'!$O:$O, 'CAP CONDUÇÃO 90º'!$P:$P, 'CAP CONDUÇÃO 90º'!$Q:$Q, 'CAP CONDUÇÃO 90º'!$R:$R, 'CAP CONDUÇÃO 90º'!$S:$S, 'CAP CONDUÇÃO 90º'!$T:$T ) ), 0 ), MATCH(BI6, IF(AV6="PVC", CHOOSE( MATCH(AU6, {"A1 - 2";"A1 - 3";"A2 - 2";"A2 - 3";"B1 - 2";"B1 - 3";"B2 - 2";"B2 - 3";"C - 2";"C - 3";"D - 2";"D - 3";"E - 2";"E - 3";"F - 2";"F - 3TRI";"F - 3JUST";"G - 3HOR";"G - 3VER"}, 0), 'CAP CONDUÇÃO 70º'!$B:$B, 'CAP CONDUÇÃO 70º'!$C:$C, 'CAP CONDUÇÃO 70º'!$D:$D, 'CAP CONDUÇÃO 70º'!$E:$E, 'CAP CONDUÇÃO 70º'!$F:$F, 'CAP CONDUÇÃO 70º'!$G:$G, 'CAP CONDUÇÃO 70º'!$H:$H, 'CAP CONDUÇÃO 70º'!$I:$I, 'CAP CONDUÇÃO 70º'!$J:$J, 'CAP CONDUÇÃO 70º'!$K:$K, 'CAP CONDUÇÃO 70º'!$L:$L, 'CAP CONDUÇÃO 70º'!$M:$M, 'CAP CONDUÇÃO 70º'!$N:$N, 'CAP CONDUÇÃO 70º'!$O:$O, 'CAP CONDUÇÃO 70º'!$P:$P, 'CAP CONDUÇÃO 70º'!$Q:$Q, 'CAP CONDUÇÃO 70º'!$R:$R, 'CAP CONDUÇÃO 70º'!$S:$S, 'CAP CONDUÇÃO 70º'!$T:$T ), CHOOSE( MATCH(AU6, {"A1 - 2";"A1 - 3";"A2 - 2";"A2 - 3";"B1 - 2";"B1 - 3";"B2 - 2";"B2 - 3";"C - 2";"C - 3";"D - 2";"D - 3";"E - 2";"E - 3";"F - 2";"F - 3TRI";"F - 3JUST";"G - 3HOR";"G - 3VER"}, 0), 'CAP CONDUÇÃO 90º'!$B:$B, 'CAP CONDUÇÃO 90º'!$C:$C, 'CAP CONDUÇÃO 90º'!$D:$D, 'CAP CONDUÇÃO 90º'!$E:$E, 'CAP CONDUÇÃO 90º'!$F:$F, 'CAP CONDUÇÃO 90º'!$G:$G, 'CAP CONDUÇÃO 90º'!$H:$H, 'CAP CONDUÇÃO 90º'!$I:$I, 'CAP CONDUÇÃO 90º'!$J:$J, 'CAP CONDUÇÃO 90º'!$K:$K, 'CAP CONDUÇÃO 90º'!$L:$L, 'CAP CONDUÇÃO 90º'!$M:$M, 'CAP CONDUÇÃO 90º'!$N:$N, 'CAP CONDUÇÃO 90º'!$O:$O, 'CAP CONDUÇÃO 90º'!$P:$P, 'CAP CONDUÇÃO 90º'!$Q:$Q, 'CAP CONDUÇÃO 90º'!$R:$R, 'CAP CONDUÇÃO 90º'!$S:$S, 'CAP CONDUÇÃO 90º'!$T:$T ) ), 1 ) + 1 ) ), "Não há valor maior ou igual" )} -> Não há valor maior ou igual | BS6: =IFERROR(IF(BP6="","","3F#"&BR6&"mm²+N"&VLOOKUP($BR$5,NEUTRO!$A:$B,2,0)&"mm²+T"&VLOOKUP($BR$5,TERRA!$A:$B,2,0)&"mm²"),"")
A7: 3 | AO7: 3 | AP7: =IF(SUMPRODUCT(B7:AO7, B$4:AO$4)=0, "", SUMPRODUCT(B7:AO7, B$4:AO$4)) -> 30000 | AQ7: =IF(AP7="","",IF((SUM(B7:K7)+SUM(AF7:AO7))>=1,1,0.92)) -> 1 | AR7: =IF(AP7="","",ROUND((AP7/AQ7),0)) -> 30000 | AY7: Em feixe: ao ar livre ou sobre superfície; embutidos; em conduto fechado (métodos A a F) | AZ7: 1 | BA7: =INDEX(AGRUPAMENTO!C5:N9,MATCH(AY7,AGRUPAMENTO!B5:B9,0),MATCH(AZ7,AGRUPAMENTO!C4:N4,0)) -> #N/A | BB7: NÃO SUBTERRÂNEA | BC7: 30 | BD7: =IF(BB7="SUBTERRÂNEA",IF(AV7="PVC",VLOOKUP(BC7,TEMPERATURA!G4:H18,2,0),VLOOKUP(BC7,TEMPERATURA!G4:I18,3,0)),IF(AV7="PVC",VLOOKUP(BC7,TEMPERATURA!B4:C18,2,0),VLOOKUP(BC7,TEMPERATURA!B4:D18,3,0))) -> 1 | BE7: =IF( AP7="", "", _xlfn.IFS( $BI$111="127/220", IF( BH7=1, 127, IF( BH7=2, ROUND(127*SQRT(3),0), IF( BH7=3, ROUND(127*SQRT(3),0), "" ) ) ), $BI$111="220/380", IF( BH7=1, 220, IF( BH7=2, ROUND(220*SQRT(3),0)-1, IF( BH7=3, ROUND(220*SQRT(3),0)-1, "" ) ) ), $BI$111="254/440", IF( BH7=1, 254, IF( BH7=2, ROUND(254*SQRT(3),0), IF( BH7=3, ROUND(254*SQRT(3),0), "" ) ) ) ) ) -> 127 | BF7: =IF(AP7="","",ROUND(AR7/IF(BH7=1,127,IF(BH7=2,220,IF(BH7=3,381,""))),1)) -> 236.2 | BG7: =(BF7*AX7)/(BD7*BA7) -> #N/A | BH7: =IF(COUNTA(BJ7:BL7)=0,"",COUNTA(BJ7:BL7)) -> 1 | BI7: =IF(AP7="","", IF(COUNTA(V7:AE7)>=1, MAX(IFERROR(_xlfn.AGGREGATE(15,6,DISJUNTORES!$C$2:$C$100/(DISJUNTORES!$C$2:$C$100>=BF7),1),""),25), IF(COUNTA(L7:U7)>=1, MAX(IFERROR(_xlfn.AGGREGATE(15,6,DISJUNTORES!$C$2:$C$100/(DISJUNTORES!$C$2:$C$100>=BF7),1),""),20), IF(COUNTA(A7:K7)>=1, MAX(IFERROR(_xlfn.AGGREGATE(15,6,DISJUNTORES!$C$2:$C$100/(DISJUNTORES!$C$2:$C$100>=BF7),1),""),16), IFERROR(_xlfn.AGGREGATE(15,6,DISJUNTORES!$C$2:$C$100/(DISJUNTORES!$C$2:$C$100>=BF7),1),""))))) -> 250 | BJ7: x | BM7: =IF(IF(BJ7="","",AR7/COUNTA(BJ7:BL7))=0,"",IF(BJ7="","",AR7/COUNTA(BJ7:BL7))) -> 30000 | BN7: =IF(IF(BK7="","",AR7/COUNTA(BJ7:BL7))=0,"",IF(BK7="","",AR7/COUNTA(BJ7:BL7))) | BO7: =IF(IF(BL7="","",AR7/COUNTA(BJ7:BL7))=0,"",IF(BL7="","",AR7/COUNTA(BJ7:BL7))) | BP7: {=IFERROR( INDEX( IF(AV7="PVC", 'CAP CONDUÇÃO 70º'!$A:$A, 'CAP CONDUÇÃO 90º'!$A:$A), IF( COUNTIF( IF(AV7="PVC", CHOOSE( MATCH(AU7, {"A1 - 2";"A1 - 3";"A2 - 2";"A2 - 3";"B1 - 2";"B1 - 3";"B2 - 2";"B2 - 3";"C - 2";"C - 3";"D - 2";"D - 3";"E - 2";"E - 3";"F - 2";"F - 3TRI";"F - 3JUST";"G - 3HOR";"G - 3VER"}, 0), 'CAP CONDUÇÃO 70º'!$B:$B, 'CAP CONDUÇÃO 70º'!$C:$C, 'CAP CONDUÇÃO 70º'!$D:$D, 'CAP CONDUÇÃO 70º'!$E:$E, 'CAP CONDUÇÃO 70º'!$F:$F, 'CAP CONDUÇÃO 70º'!$G:$G, 'CAP CONDUÇÃO 70º'!$H:$H, 'CAP CONDUÇÃO 70º'!$I:$I, 'CAP CONDUÇÃO 70º'!$J:$J, 'CAP CONDUÇÃO 70º'!$K:$K, 'CAP CONDUÇÃO 70º'!$L:$L, 'CAP CONDUÇÃO 70º'!$M:$M, 'CAP CONDUÇÃO 70º'!$N:$N, 'CAP CONDUÇÃO 70º'!$O:$O, 'CAP CONDUÇÃO 70º'!$P:$P, 'CAP CONDUÇÃO 70º'!$Q:$Q, 'CAP CONDUÇÃO 70º'!$R:$R, 'CAP CONDUÇÃO 70º'!$S:$S, 'CAP CONDUÇÃO 70º'!$T:$T ), CHOOSE( MATCH(AU7, {"A1 - 2";"A1 - 3";"A2 - 2";"A2 - 3";"B1 - 2";"B1 - 3";"B2 - 2";"B2 - 3";"C - 2";"C - 3";"D - 2";"D - 3";"E - 2";"E - 3";"F - 2";"F - 3TRI";"F - 3JUST";"G - 3HOR";"G - 3VER"}, 0), 'CAP CONDUÇÃO 90º'!$B:$B, 'CAP CONDUÇÃO 90º'!$C:$C, 'CAP CONDUÇÃO 90º'!$D:$D, 'CAP CONDUÇÃO 90º'!$E:$E, 'CAP CONDUÇÃO 90º'!$F:$F, 'CAP CONDUÇÃO 90º'!$G:$G, 'CAP CONDUÇÃO 90º'!$H:$H, 'CAP CONDUÇÃO 90º'!$I:$I, 'CAP CONDUÇÃO 90º'!$J:$J, 'CAP CONDUÇÃO 90º'!$K:$K, 'CAP CONDUÇÃO 90º'!$L:$L, 'CAP CONDUÇÃO 90º'!$M:$M, 'CAP CONDUÇÃO 90º'!$N:$N, 'CAP CONDUÇÃO 90º'!$O:$O, 'CAP CONDUÇÃO 90º'!$P:$P, 'CAP CONDUÇÃO 90º'!$Q:$Q, 'CAP CONDUÇÃO 90º'!$R:$R, 'CAP CONDUÇÃO 90º'!$S:$S, 'CAP CONDUÇÃO 90º'!$T:$T ) ), BI7 ) > 0, MATCH(BI7, IF(AV7="PVC", CHOOSE( MATCH(AU7, {"A1 - 2";"A1 - 3";"A2 - 2";"A2 - 3";"B1 - 2";"B1 - 3";"B2 - 2";"B2 - 3";"C - 2";"C - 3";"D - 2";"D - 3";"E - 2";"E - 3";"F - 2";"F - 3TRI";"F - 3JUST";"G - 3HOR";"G - 3VER"}, 0), 'CAP CONDUÇÃO 70º'!$B:$B, 'CAP CONDUÇÃO 70º'!$C:$C, 'CAP CONDUÇÃO 70º'!$D:$D, 'CAP CONDUÇÃO 70º'!$E:$E, 'CAP CONDUÇÃO 70º'!$F:$F, 'CAP CONDUÇÃO 70º'!$G:$G, 'CAP CONDUÇÃO 70º'!$H:$H, 'CAP CONDUÇÃO 70º'!$I:$I, 'CAP CONDUÇÃO 70º'!$J:$J, 'CAP CONDUÇÃO 70º'!$K:$K, 'CAP CONDUÇÃO 70º'!$L:$L, 'CAP CONDUÇÃO 70º'!$M:$M, 'CAP CONDUÇÃO 70º'!$N:$N, 'CAP CONDUÇÃO 70º'!$O:$O, 'CAP CONDUÇÃO 70º'!$P:$P, 'CAP CONDUÇÃO 70º'!$Q:$Q, 'CAP CONDUÇÃO 70º'!$R:$R, 'CAP CONDUÇÃO 70º'!$S:$S, 'CAP CONDUÇÃO 70º'!$T:$T ), CHOOSE( MATCH(AU7, {"A1 - 2";"A1 - 3";"A2 - 2";"A2 - 3";"B1 - 2";"B1 - 3";"B2 - 2";"B2 - 3";"C - 2";"C - 3";"D - 2";"D - 3";"E - 2";"E - 3";"F - 2";"F - 3TRI";"F - 3JUST";"G - 3HOR";"G - 3VER"}, 0), 'CAP CONDUÇÃO 90º'!$B:$B, 'CAP CONDUÇÃO 90º'!$C:$C, 'CAP CONDUÇÃO 90º'!$D:$D, 'CAP CONDUÇÃO 90º'!$E:$E, 'CAP CONDUÇÃO 90º'!$F:$F, 'CAP CONDUÇÃO 90º'!$G:$G, 'CAP CONDUÇÃO 90º'!$H:$H, 'CAP CONDUÇÃO 90º'!$I:$I, 'CAP CONDUÇÃO 90º'!$J:$J, 'CAP CONDUÇÃO 90º'!$K:$K, 'CAP CONDUÇÃO 90º'!$L:$L, 'CAP CONDUÇÃO 90º'!$M:$M, 'CAP CONDUÇÃO 90º'!$N:$N, 'CAP CONDUÇÃO 90º'!$O:$O, 'CAP CONDUÇÃO 90º'!$P:$P, 'CAP CONDUÇÃO 90º'!$Q:$Q, 'CAP CONDUÇÃO 90º'!$R:$R, 'CAP CONDUÇÃO 90º'!$S:$S, 'CAP CONDUÇÃO 90º'!$T:$T ) ), 0 ), MATCH(BI7, IF(AV7="PVC", CHOOSE( MATCH(AU7, {"A1 - 2";"A1 - 3";"A2 - 2";"A2 - 3";"B1 - 2";"B1 - 3";"B2 - 2";"B2 - 3";"C - 2";"C - 3";"D - 2";"D - 3";"E - 2";"E - 3";"F - 2";"F - 3TRI";"F - 3JUST";"G - 3HOR";"G - 3VER"}, 0), 'CAP CONDUÇÃO 70º'!$B:$B, 'CAP CONDUÇÃO 70º'!$C:$C, 'CAP CONDUÇÃO 70º'!$D:$D, 'CAP CONDUÇÃO 70º'!$E:$E, 'CAP CONDUÇÃO 70º'!$F:$F, 'CAP CONDUÇÃO 70º'!$G:$G, 'CAP CONDUÇÃO 70º'!$H:$H, 'CAP CONDUÇÃO 70º'!$I:$I, 'CAP CONDUÇÃO 70º'!$J:$J, 'CAP CONDUÇÃO 70º'!$K:$K, 'CAP CONDUÇÃO 70º'!$L:$L, 'CAP CONDUÇÃO 70º'!$M:$M, 'CAP CONDUÇÃO 70º'!$N:$N, 'CAP CONDUÇÃO 70º'!$O:$O, 'CAP CONDUÇÃO 70º'!$P:$P, 'CAP CONDUÇÃO 70º'!$Q:$Q, 'CAP CONDUÇÃO 70º'!$R:$R, 'CAP CONDUÇÃO 70º'!$S:$S, 'CAP CONDUÇÃO 70º'!$T:$T ), CHOOSE( MATCH(AU7, {"A1 - 2";"A1 - 3";"A2 - 2";"A2 - 3";"B1 - 2";"B1 - 3";"B2 - 2";"B2 - 3";"C - 2";"C - 3";"D - 2";"D - 3";"E - 2";"E - 3";"F - 2";"F - 3TRI";"F - 3JUST";"G - 3HOR";"G - 3VER"}, 0), 'CAP CONDUÇÃO 90º'!$B:$B, 'CAP CONDUÇÃO 90º'!$C:$C, 'CAP CONDUÇÃO 90º'!$D:$D, 'CAP CONDUÇÃO 90º'!$E:$E, 'CAP CONDUÇÃO 90º'!$F:$F, 'CAP CONDUÇÃO 90º'!$G:$G, 'CAP CONDUÇÃO 90º'!$H:$H, 'CAP CONDUÇÃO 90º'!$I:$I, 'CAP CONDUÇÃO 90º'!$J:$J, 'CAP CONDUÇÃO 90º'!$K:$K, 'CAP CONDUÇÃO 90º'!$L:$L, 'CAP CONDUÇÃO 90º'!$M:$M, 'CAP CONDUÇÃO 90º'!$N:$N, 'CAP CONDUÇÃO 90º'!$O:$O, 'CAP CONDUÇÃO 90º'!$P:$P, 'CAP CONDUÇÃO 90º'!$Q:$Q, 'CAP CONDUÇÃO 90º'!$R:$R, 'CAP CONDUÇÃO 90º'!$S:$S, 'CAP CONDUÇÃO 90º'!$T:$T ) ), 1 ) + 1 ) ), "Não há valor maior ou igual" )} -> Não há valor maior ou igual | BS7: =IFERROR(IF(BP7="","","3F#"&BR7&"mm²+N"&VLOOKUP($BR$5,NEUTRO!$A:$B,2,0)&"mm²+T"&VLOOKUP($BR$5,TERRA!$A:$B,2,0)&"mm²"),"")
A8: 4 | AN8: 4 | AP8: =IF(SUMPRODUCT(B8:AO8, B$4:AO$4)=0, "", SUMPRODUCT(B8:AO8, B$4:AO$4)) | AQ8: =IF(AP8="","",IF((SUM(B8:K8)+SUM(AF8:AO8))>=1,1,0.92)) | AR8: =IF(AP8="","",ROUND((AP8/AQ8),0)) | AY8: Em feixe: ao ar livre ou sobre superfície; embutidos; em conduto fechado (métodos A a F) | AZ8: 1 | BA8: =INDEX(AGRUPAMENTO!C6:N10,MATCH(AY8,AGRUPAMENTO!B6:B10,0),MATCH(AZ8,AGRUPAMENTO!C5:N5,0)) -> #N/A | BB8: NÃO SUBTERRÂNEA | BC8: 30 | BD8: =IF(BB8="SUBTERRÂNEA",IF(AV8="PVC",VLOOKUP(BC8,TEMPERATURA!G5:H19,2,0),VLOOKUP(BC8,TEMPERATURA!G5:I19,3,0)),IF(AV8="PVC",VLOOKUP(BC8,TEMPERATURA!B5:C19,2,0),VLOOKUP(BC8,TEMPERATURA!B5:D19,3,0))) -> 1 | BE8: =IF( AP8="", "", _xlfn.IFS( $BI$111="127/220", IF( BH8=1, 127, IF( BH8=2, ROUND(127*SQRT(3),0), IF( BH8=3, ROUND(127*SQRT(3),0), "" ) ) ), $BI$111="220/380", IF( BH8=1, 220, IF( BH8=2, ROUND(220*SQRT(3),0)-1, IF( BH8=3, ROUND(220*SQRT(3),0)-1, "" ) ) ), $BI$111="254/440", IF( BH8=1, 254, IF( BH8=2, ROUND(254*SQRT(3),0), IF( BH8=3, ROUND(254*SQRT(3),0), "" ) ) ) ) ) | BF8: =IF(AP8="","",ROUND(AR8/IF(BH8=1,127,IF(BH8=2,220,IF(BH8=3,381,""))),1)) | BG8: =(BF8*AX8)/(BD8*BA8) -> #VALUE! | BH8: =IF(COUNTA(BJ8:BL8)=0,"",COUNTA(BJ8:BL8)) -> 1 | BI8: =IF(AP8="","", IF(COUNTA(V8:AE8)>=1, MAX(IFERROR(_xlfn.AGGREGATE(15,6,DISJUNTORES!$C$2:$C$100/(DISJUNTORES!$C$2:$C$100>=BF8),1),""),25), IF(COUNTA(L8:U8)>=1, MAX(IFERROR(_xlfn.AGGREGATE(15,6,DISJUNTORES!$C$2:$C$100/(DISJUNTORES!$C$2:$C$100>=BF8),1),""),20), IF(COUNTA(A8:K8)>=1, MAX(IFERROR(_xlfn.AGGREGATE(15,6,DISJUNTORES!$C$2:$C$100/(DISJUNTORES!$C$2:$C$100>=BF8),1),""),16), IFERROR(_xlfn.AGGREGATE(15,6,DISJUNTORES!$C$2:$C$100/(DISJUNTORES!$C$2:$C$100>=BF8),1),""))))) | BJ8: x | BM8: =IF(IF(BJ8="","",AR8/COUNTA(BJ8:BL8))=0,"",IF(BJ8="","",AR8/COUNTA(BJ8:BL8))) -> #VALUE! | BN8: =IF(IF(BK8="","",AR8/COUNTA(BJ8:BL8))=0,"",IF(BK8="","",AR8/COUNTA(BJ8:BL8))) | BO8: =IF(IF(BL8="","",AR8/COUNTA(BJ8:BL8))=0,"",IF(BL8="","",AR8/COUNTA(BJ8:BL8))) | BP8: {=IFERROR( INDEX( IF(AV8="PVC", 'CAP CONDUÇÃO 70º'!$A:$A, 'CAP CONDUÇÃO 90º'!$A:$A), IF( COUNTIF( IF(AV8="PVC", CHOOSE( MATCH(AU8, {"A1 - 2";"A1 - 3";"A2 - 2";"A2 - 3";"B1 - 2";"B1 - 3";"B2 - 2";"B2 - 3";"C - 2";"C - 3";"D - 2";"D - 3";"E - 2";"E - 3";"F - 2";"F - 3TRI";"F - 3JUST";"G - 3HOR";"G - 3VER"}, 0), 'CAP CONDUÇÃO 70º'!$B:$B, 'CAP CONDUÇÃO 70º'!$C:$C, 'CAP CONDUÇÃO 70º'!$D:$D, 'CAP CONDUÇÃO 70º'!$E:$E, 'CAP CONDUÇÃO 70º'!$F:$F, 'CAP CONDUÇÃO 70º'!$G:$G, 'CAP CONDUÇÃO 70º'!$H:$H, 'CAP CONDUÇÃO 70º'!$I:$I, 'CAP CONDUÇÃO 70º'!$J:$J, 'CAP CONDUÇÃO 70º'!$K:$K, 'CAP CONDUÇÃO 70º'!$L:$L, 'CAP CONDUÇÃO 70º'!$M:$M, 'CAP CONDUÇÃO 70º'!$N:$N, 'CAP CONDUÇÃO 70º'!$O:$O, 'CAP CONDUÇÃO 70º'!$P:$P, 'CAP CONDUÇÃO 70º'!$Q:$Q, 'CAP CONDUÇÃO 70º'!$R:$R, 'CAP CONDUÇÃO 70º'!$S:$S, 'CAP CONDUÇÃO 70º'!$T:$T ), CHOOSE( MATCH(AU8, {"A1 - 2";"A1 - 3";"A2 - 2";"A2 - 3";"B1 - 2";"B1 - 3";"B2 - 2";"B2 - 3";"C - 2";"C - 3";"D - 2";"D - 3";"E - 2";"E - 3";"F - 2";"F - 3TRI";"F - 3JUST";"G - 3HOR";"G - 3VER"}, 0), 'CAP CONDUÇÃO 90º'!$B:$B, 'CAP CONDUÇÃO 90º'!$C:$C, 'CAP CONDUÇÃO 90º'!$D:$D, 'CAP CONDUÇÃO 90º'!$E:$E, 'CAP CONDUÇÃO 90º'!$F:$F, 'CAP CONDUÇÃO 90º'!$G:$G, 'CAP CONDUÇÃO 90º'!$H:$H, 'CAP CONDUÇÃO 90º'!$I:$I, 'CAP CONDUÇÃO 90º'!$J:$J, 'CAP CONDUÇÃO 90º'!$K:$K, 'CAP CONDUÇÃO 90º'!$L:$L, 'CAP CONDUÇÃO 90º'!$M:$M, 'CAP CONDUÇÃO 90º'!$N:$N, 'CAP CONDUÇÃO 90º'!$O:$O, 'CAP CONDUÇÃO 90º'!$P:$P, 'CAP CONDUÇÃO 90º'!$Q:$Q, 'CAP CONDUÇÃO 90º'!$R:$R, 'CAP CONDUÇÃO 90º'!$S:$S, 'CAP CONDUÇÃO 90º'!$T:$T ) ), BI8 ) > 0, MATCH(BI8, IF(AV8="PVC", CHOOSE( MATCH(AU8, {"A1 - 2";"A1 - 3";"A2 - 2";"A2 - 3";"B1 - 2";"B1 - 3";"B2 - 2";"B2 - 3";"C - 2";"C - 3";"D - 2";"D - 3";"E - 2";"E - 3";"F - 2";"F - 3TRI";"F - 3JUST";"G - 3HOR";"G - 3VER"}, 0), 'CAP CONDUÇÃO 70º'!$B:$B, 'CAP CONDUÇÃO 70º'!$C:$C, 'CAP CONDUÇÃO 70º'!$D:$D, 'CAP CONDUÇÃO 70º'!$E:$E, 'CAP CONDUÇÃO 70º'!$F:$F, 'CAP CONDUÇÃO 70º'!$G:$G, 'CAP CONDUÇÃO 70º'!$H:$H, 'CAP CONDUÇÃO 70º'!$I:$I, 'CAP CONDUÇÃO 70º'!$J:$J, 'CAP CONDUÇÃO 70º'!$K:$K, 'CAP CONDUÇÃO 70º'!$L:$L, 'CAP CONDUÇÃO 70º'!$M:$M, 'CAP CONDUÇÃO 70º'!$N:$N, 'CAP CONDUÇÃO 70º'!$O:$O, 'CAP CONDUÇÃO 70º'!$P:$P, 'CAP CONDUÇÃO 70º'!$Q:$Q, 'CAP CONDUÇÃO 70º'!$R:$R, 'CAP CONDUÇÃO 70º'!$S:$S, 'CAP CONDUÇÃO 70º'!$T:$T ), CHOOSE( MATCH(AU8, {"A1 - 2";"A1 - 3";"A2 - 2";"A2 - 3";"B1 - 2";"B1 - 3";"B2 - 2";"B2 - 3";"C - 2";"C - 3";"D - 2";"D - 3";"E - 2";"E - 3";"F - 2";"F - 3TRI";"F - 3JUST";"G - 3HOR";"G - 3VER"}, 0), 'CAP CONDUÇÃO 90º'!$B:$B, 'CAP CONDUÇÃO 90º'!$C:$C, 'CAP CONDUÇÃO 90º'!$D:$D, 'CAP CONDUÇÃO 90º'!$E:$E, 'CAP CONDUÇÃO 90º'!$F:$F, 'CAP CONDUÇÃO 90º'!$G:$G, 'CAP CONDUÇÃO 90º'!$H:$H, 'CAP CONDUÇÃO 90º'!$I:$I, 'CAP CONDUÇÃO 90º'!$J:$J, 'CAP CONDUÇÃO 90º'!$K:$K, 'CAP CONDUÇÃO 90º'!$L:$L, 'CAP CONDUÇÃO 90º'!$M:$M, 'CAP CONDUÇÃO 90º'!$N:$N, 'CAP CONDUÇÃO 90º'!$O:$O, 'CAP CONDUÇÃO 90º'!$P:$P, 'CAP CONDUÇÃO 90º'!$Q:$Q, 'CAP CONDUÇÃO 90º'!$R:$R, 'CAP CONDUÇÃO 90º'!$S:$S, 'CAP CONDUÇÃO 90º'!$T:$T ) ), 0 ), MATCH(BI8, IF(AV8="PVC", CHOOSE( MATCH(AU8, {"A1 - 2";"A1 - 3";"A2 - 2";"A2 - 3";"B1 - 2";"B1 - 3";"B2 - 2";"B2 - 3";"C - 2";"C - 3";"D - 2";"D - 3";"E - 2";"E - 3";"F - 2";"F - 3TRI";"F - 3JUST";"G - 3HOR";"G - 3VER"}, 0), 'CAP CONDUÇÃO 70º'!$B:$B, 'CAP CONDUÇÃO 70º'!$C:$C, 'CAP CONDUÇÃO 70º'!$D:$D, 'CAP CONDUÇÃO 70º'!$E:$E, 'CAP CONDUÇÃO 70º'!$F:$F, 'CAP CONDUÇÃO 70º'!$G:$G, 'CAP CONDUÇÃO 70º'!$H:$H, 'CAP CONDUÇÃO 70º'!$I:$I, 'CAP CONDUÇÃO 70º'!$J:$J, 'CAP CONDUÇÃO 70º'!$K:$K, 'CAP CONDUÇÃO 70º'!$L:$L, 'CAP CONDUÇÃO 70º'!$M:$M, 'CAP CONDUÇÃO 70º'!$N:$N, 'CAP CONDUÇÃO 70º'!$O:$O, 'CAP CONDUÇÃO 70º'!$P:$P, 'CAP CONDUÇÃO 70º'!$Q:$Q, 'CAP CONDUÇÃO 70º'!$R:$R, 'CAP CONDUÇÃO 70º'!$S:$S, 'CAP CONDUÇÃO 70º'!$T:$T ), CHOOSE( MATCH(AU8, {"A1 - 2";"A1 - 3";"A2 - 2";"A2 - 3";"B1 - 2";"B1 - 3";"B2 - 2";"B2 - 3";"C - 2";"C - 3";"D - 2";"D - 3";"E - 2";"E - 3";"F - 2";"F - 3TRI";"F - 3JUST";"G - 3HOR";"G - 3VER"}, 0), 'CAP CONDUÇÃO 90º'!$B:$B, 'CAP CONDUÇÃO 90º'!$C:$C, 'CAP CONDUÇÃO 90º'!$D:$D, 'CAP CONDUÇÃO 90º'!$E:$E, 'CAP CONDUÇÃO 90º'!$F:$F, 'CAP CONDUÇÃO 90º'!$G:$G, 'CAP CONDUÇÃO 90º'!$H:$H, 'CAP CONDUÇÃO 90º'!$I:$I, 'CAP CONDUÇÃO 90º'!$J:$J, 'CAP CONDUÇÃO 90º'!$K:$K, 'CAP CONDUÇÃO 90º'!$L:$L, 'CAP CONDUÇÃO 90º'!$M:$M, 'CAP CONDUÇÃO 90º'!$N:$N, 'CAP CONDUÇÃO 90º'!$O:$O, 'CAP CONDUÇÃO 90º'!$P:$P, 'CAP CONDUÇÃO 90º'!$Q:$Q, 'CAP CONDUÇÃO 90º'!$R:$R, 'CAP CONDUÇÃO 90º'!$S:$S, 'CAP CONDUÇÃO 90º'!$T:$T ) ), 1 ) + 1 ) ), "Não há valor maior ou igual" )} -> Não há valor maior ou igual | BS8: =IFERROR(IF(BP8="","","3F#"&BR8&"mm²+N"&VLOOKUP($BR$5,NEUTRO!$A:$B,2,0)&"mm²+T"&VLOOKUP($BR$5,TERRA!$A:$B,2,0)&"mm²"),"")
A9: 5 | AP9: =IF(SUMPRODUCT(B9:AO9, B$4:AO$4)=0, "", SUMPRODUCT(B9:AO9, B$4:AO$4)) | AQ9: =IF(AP9="","",IF((SUM(B9:K9)+SUM(AF9:AO9))>=1,1,0.92)) | AR9: =IF(AP9="","",ROUND((AP9/AQ9),0)) | AY9: Em feixe: ao ar livre ou sobre superfície; embutidos; em conduto fechado (métodos A a F) | AZ9: 1 | BA9: =INDEX(AGRUPAMENTO!C7:N11,MATCH(AY9,AGRUPAMENTO!B7:B11,0),MATCH(AZ9,AGRUPAMENTO!C6:N6,0)) -> #N/A | BB9: NÃO SUBTERRÂNEA | BC9: 30 | BD9: =IF(BB9="SUBTERRÂNEA",IF(AV9="PVC",VLOOKUP(BC9,TEMPERATURA!G6:H20,2,0),VLOOKUP(BC9,TEMPERATURA!G6:I20,3,0)),IF(AV9="PVC",VLOOKUP(BC9,TEMPERATURA!B6:C20,2,0),VLOOKUP(BC9,TEMPERATURA!B6:D20,3,0))) -> 1 | BE9: =IF( AP9="", "", _xlfn.IFS( $BI$111="127/220", IF( BH9=1, 127, IF( BH9=2, ROUND(127*SQRT(3),0), IF( BH9=3, ROUND(127*SQRT(3),0), "" ) ) ), $BI$111="220/380", IF( BH9=1, 220, IF( BH9=2, ROUND(220*SQRT(3),0)-1, IF( BH9=3, ROUND(220*SQRT(3),0)-1, "" ) ) ), $BI$111="254/440", IF( BH9=1, 254, IF( BH9=2, ROUND(254*SQRT(3),0), IF( BH9=3, ROUND(254*SQRT(3),0), "" ) ) ) ) ) | BF9: =IF(AP9="","",ROUND(AR9/IF(BH9=1,127,IF(BH9=2,220,IF(BH9=3,381,""))),1)) | BG9: =(BF9*AX9)/(BD9*BA9) -> #VALUE! | BH9: =IF(COUNTA(BJ9:BL9)=0,"",COUNTA(BJ9:BL9)) | BI9: =IF(AP9="","", IF(COUNTA(V9:AE9)>=1, MAX(IFERROR(_xlfn.AGGREGATE(15,6,DISJUNTORES!$C$2:$C$100/(DISJUNTORES!$C$2:$C$100>=BF9),1),""),25), IF(COUNTA(L9:U9)>=1, MAX(IFERROR(_xlfn.AGGREGATE(15,6,DISJUNTORES!$C$2:$C$100/(DISJUNTORES!$C$2:$C$100>=BF9),1),""),20), IF(COUNTA(A9:K9)>=1, MAX(IFERROR(_xlfn.AGGREGATE(15,6,DISJUNTORES!$C$2:$C$100/(DISJUNTORES!$C$2:$C$100>=BF9),1),""),16), IFERROR(_xlfn.AGGREGATE(15,6,DISJUNTORES!$C$2:$C$100/(DISJUNTORES!$C$2:$C$100>=BF9),1),""))))) | BM9: =IF(IF(BJ9="","",AR9/COUNTA(BJ9:BL9))=0,"",IF(BJ9="","",AR9/COUNTA(BJ9:BL9))) | BN9: =IF(IF(BK9="","",AR9/COUNTA(BJ9:BL9))=0,"",IF(BK9="","",AR9/COUNTA(BJ9:BL9))) | BO9: =IF(IF(BL9="","",AR9/COUNTA(BJ9:BL9))=0,"",IF(BL9="","",AR9/COUNTA(BJ9:BL9))) | BP9: {=IFERROR( INDEX( IF(AV9="PVC", 'CAP CONDUÇÃO 70º'!$A:$A, 'CAP CONDUÇÃO 90º'!$A:$A), IF( COUNTIF( IF(AV9="PVC", CHOOSE( MATCH(AU9, {"A1 - 2";"A1 - 3";"A2 - 2";"A2 - 3";"B1 - 2";"B1 - 3";"B2 - 2";"B2 - 3";"C - 2";"C - 3";"D - 2";"D - 3";"E - 2";"E - 3";"F - 2";"F - 3TRI";"F - 3JUST";"G - 3HOR";"G - 3VER"}, 0), 'CAP CONDUÇÃO 70º'!$B:$B, 'CAP CONDUÇÃO 70º'!$C:$C, 'CAP CONDUÇÃO 70º'!$D:$D, 'CAP CONDUÇÃO 70º'!$E:$E, 'CAP CONDUÇÃO 70º'!$F:$F, 'CAP CONDUÇÃO 70º'!$G:$G, 'CAP CONDUÇÃO 70º'!$H:$H, 'CAP CONDUÇÃO 70º'!$I:$I, 'CAP CONDUÇÃO 70º'!$J:$J, 'CAP CONDUÇÃO 70º'!$K:$K, 'CAP CONDUÇÃO 70º'!$L:$L, 'CAP CONDUÇÃO 70º'!$M:$M, 'CAP CONDUÇÃO 70º'!$N:$N, 'CAP CONDUÇÃO 70º'!$O:$O, 'CAP CONDUÇÃO 70º'!$P:$P, 'CAP CONDUÇÃO 70º'!$Q:$Q, 'CAP CONDUÇÃO 70º'!$R:$R, 'CAP CONDUÇÃO 70º'!$S:$S, 'CAP CONDUÇÃO 70º'!$T:$T ), CHOOSE( MATCH(AU9, {"A1 - 2";"A1 - 3";"A2 - 2";"A2 - 3";"B1 - 2";"B1 - 3";"B2 - 2";"B2 - 3";"C - 2";"C - 3";"D - 2";"D - 3";"E - 2";"E - 3";"F - 2";"F - 3TRI";"F - 3JUST";"G - 3HOR";"G - 3VER"}, 0), 'CAP CONDUÇÃO 90º'!$B:$B, 'CAP CONDUÇÃO 90º'!$C:$C, 'CAP CONDUÇÃO 90º'!$D:$D, 'CAP CONDUÇÃO 90º'!$E:$E, 'CAP CONDUÇÃO 90º'!$F:$F, 'CAP CONDUÇÃO 90º'!$G:$G, 'CAP CONDUÇÃO 90º'!$H:$H, 'CAP CONDUÇÃO 90º'!$I:$I, 'CAP CONDUÇÃO 90º'!$J:$J, 'CAP CONDUÇÃO 90º'!$K:$K, 'CAP CONDUÇÃO 90º'!$L:$L, 'CAP CONDUÇÃO 90º'!$M:$M, 'CAP CONDUÇÃO 90º'!$N:$N, 'CAP CONDUÇÃO 90º'!$O:$O, 'CAP CONDUÇÃO 90º'!$P:$P, 'CAP CONDUÇÃO 90º'!$Q:$Q, 'CAP CONDUÇÃO 90º'!$R:$R, 'CAP CONDUÇÃO 90º'!$S:$S, 'CAP CONDUÇÃO 90º'!$T:$T ) ), BI9 ) > 0, MATCH(BI9, IF(AV9="PVC", CHOOSE( MATCH(AU9, {"A1 - 2";"A1 - 3";"A2 - 2";"A2 - 3";"B1 - 2";"B1 - 3";"B2 - 2";"B2 - 3";"C - 2";"C - 3";"D - 2";"D - 3";"E - 2";"E - 3";"F - 2";"F - 3TRI";"F - 3JUST";"G - 3HOR";"G - 3VER"}, 0), 'CAP CONDUÇÃO 70º'!$B:$B, 'CAP CONDUÇÃO 70º'!$C:$C, 'CAP CONDUÇÃO 70º'!$D:$D, 'CAP CONDUÇÃO 70º'!$E:$E, 'CAP CONDUÇÃO 70º'!$F:$F, 'CAP CONDUÇÃO 70º'!$G:$G, 'CAP CONDUÇÃO 70º'!$H:$H, 'CAP CONDUÇÃO 70º'!$I:$I, 'CAP CONDUÇÃO 70º'!$J:$J, 'CAP CONDUÇÃO 70º'!$K:$K, 'CAP CONDUÇÃO 70º'!$L:$L, 'CAP CONDUÇÃO 70º'!$M:$M, 'CAP CONDUÇÃO 70º'!$N:$N, 'CAP CONDUÇÃO 70º'!$O:$O, 'CAP CONDUÇÃO 70º'!$P:$P, 'CAP CONDUÇÃO 70º'!$Q:$Q, 'CAP CONDUÇÃO 70º'!$R:$R, 'CAP CONDUÇÃO 70º'!$S:$S, 'CAP CONDUÇÃO 70º'!$T:$T ), CHOOSE( MATCH(AU9, {"A1 - 2";"A1 - 3";"A2 - 2";"A2 - 3";"B1 - 2";"B1 - 3";"B2 - 2";"B2 - 3";"C - 2";"C - 3";"D - 2";"D - 3";"E - 2";"E - 3";"F - 2";"F - 3TRI";"F - 3JUST";"G - 3HOR";"G - 3VER"}, 0), 'CAP CONDUÇÃO 90º'!$B:$B, 'CAP CONDUÇÃO 90º'!$C:$C, 'CAP CONDUÇÃO 90º'!$D:$D, 'CAP CONDUÇÃO 90º'!$E:$E, 'CAP CONDUÇÃO 90º'!$F:$F, 'CAP CONDUÇÃO 90º'!$G:$G, 'CAP CONDUÇÃO 90º'!$H:$H, 'CAP CONDUÇÃO 90º'!$I:$I, 'CAP CONDUÇÃO 90º'!$J:$J, 'CAP CONDUÇÃO 90º'!$K:$K, 'CAP CONDUÇÃO 90º'!$L:$L, 'CAP CONDUÇÃO 90º'!$M:$M, 'CAP CONDUÇÃO 90º'!$N:$N, 'CAP CONDUÇÃO 90º'!$O:$O, 'CAP CONDUÇÃO 90º'!$P:$P, 'CAP CONDUÇÃO 90º'!$Q:$Q, 'CAP CONDUÇÃO 90º'!$R:$R, 'CAP CONDUÇÃO 90º'!$S:$S, 'CAP CONDUÇÃO 90º'!$T:$T ) ), 0 ), MATCH(BI9, IF(AV9="PVC", CHOOSE( MATCH(AU9, {"A1 - 2";"A1 - 3";"A2 - 2";"A2 - 3";"B1 - 2";"B1 - 3";"B2 - 2";"B2 - 3";"C - 2";"C - 3";"D - 2";"D - 3";"E - 2";"E - 3";"F - 2";"F - 3TRI";"F - 3JUST";"G - 3HOR";"G - 3VER"}, 0), 'CAP CONDUÇÃO 70º'!$B:$B, 'CAP CONDUÇÃO 70º'!$C:$C, 'CAP CONDUÇÃO 70º'!$D:$D, 'CAP CONDUÇÃO 70º'!$E:$E, 'CAP CONDUÇÃO 70º'!$F:$F, 'CAP CONDUÇÃO 70º'!$G:$G, 'CAP CONDUÇÃO 70º'!$H:$H, 'CAP CONDUÇÃO 70º'!$I:$I, 'CAP CONDUÇÃO 70º'!$J:$J, 'CAP CONDUÇÃO 70º'!$K:$K, 'CAP CONDUÇÃO 70º'!$L:$L, 'CAP CONDUÇÃO 70º'!$M:$M, 'CAP CONDUÇÃO 70º'!$N:$N, 'CAP CONDUÇÃO 70º'!$O:$O, 'CAP CONDUÇÃO 70º'!$P:$P, 'CAP CONDUÇÃO 70º'!$Q:$Q, 'CAP CONDUÇÃO 70º'!$R:$R, 'CAP CONDUÇÃO 70º'!$S:$S, 'CAP CONDUÇÃO 70º'!$T:$T ), CHOOSE( MATCH(AU9, {"A1 - 2";"A1 - 3";"A2 - 2";"A2 - 3";"B1 - 2";"B1 - 3";"B2 - 2";"B2 - 3";"C - 2";"C - 3";"D - 2";"D - 3";"E - 2";"E - 3";"F - 2";"F - 3TRI";"F - 3JUST";"G - 3HOR";"G - 3VER"}, 0), 'CAP CONDUÇÃO 90º'!$B:$B, 'CAP CONDUÇÃO 90º'!$C:$C, 'CAP CONDUÇÃO 90º'!$D:$D, 'CAP CONDUÇÃO 90º'!$E:$E, 'CAP CONDUÇÃO 90º'!$F:$F, 'CAP CONDUÇÃO 90º'!$G:$G, 'CAP CONDUÇÃO 90º'!$H:$H, 'CAP CONDUÇÃO 90º'!$I:$I, 'CAP CONDUÇÃO 90º'!$J:$J, 'CAP CONDUÇÃO 90º'!$K:$K, 'CAP CONDUÇÃO 90º'!$L:$L, 'CAP CONDUÇÃO 90º'!$M:$M, 'CAP CONDUÇÃO 90º'!$N:$N, 'CAP CONDUÇÃO 90º'!$O:$O, 'CAP CONDUÇÃO 90º'!$P:$P, 'CAP CONDUÇÃO 90º'!$Q:$Q, 'CAP CONDUÇÃO 90º'!$R:$R, 'CAP CONDUÇÃO 90º'!$S:$S, 'CAP CONDUÇÃO 90º'!$T:$T ) ), 1 ) + 1 ) ), "Não há valor maior ou igual" )} -> Não há valor maior ou igual | BS9: =IFERROR(IF(BP9="","","3F#"&BR9&"mm²+N"&VLOOKUP($BR$5,NEUTRO!$A:$B,2,0)&"mm²+T"&VLOOKUP($BR$5,TERRA!$A:$B,2,0)&"mm²"),"")
A10: 6 | AP10: =IF(SUMPRODUCT(B10:AO10, B$4:AO$4)=0, "", SUMPRODUCT(B10:AO10, B$4:AO$4)) | AQ10: =IF(AP10="","",IF((SUM(B10:K10)+SUM(AF10:AO10))>=1,1,0.92)) | AR10: =IF(AP10="","",ROUND((AP10/AQ10),0)) | AY10: Em feixe: ao ar livre ou sobre superfície; embutidos; em conduto fechado (métodos A a F) | AZ10: 1 | BA10: =INDEX(AGRUPAMENTO!C8:N12,MATCH(AY10,AGRUPAMENTO!B8:B12,0),MATCH(AZ10,AGRUPAMENTO!C7:N7,0)) -> #N/A | BB10: NÃO SUBTERRÂNEA | BC10: 30 | BD10: =IF(BB10="SUBTERRÂNEA",IF(AV10="PVC",VLOOKUP(BC10,TEMPERATURA!G7:H21,2,0),VLOOKUP(BC10,TEMPERATURA!G7:I21,3,0)),IF(AV10="PVC",VLOOKUP(BC10,TEMPERATURA!B7:C21,2,0),VLOOKUP(BC10,TEMPERATURA!B7:D21,3,0))) -> #N/A | BE10: =IF( AP10="", "", _xlfn.IFS( $BI$111="127/220", IF( BH10=1, 127, IF( BH10=2, ROUND(127*SQRT(3),0), IF( BH10=3, ROUND(127*SQRT(3),0), "" ) ) ), $BI$111="220/380", IF( BH10=1, 220, IF( BH10=2, ROUND(220*SQRT(3),0)-1, IF( BH10=3, ROUND(220*SQRT(3),0)-1, "" ) ) ), $BI$111="254/440", IF( BH10=1, 254, IF( BH10=2, ROUND(254*SQRT(3),0), IF( BH10=3, ROUND(254*SQRT(3),0), "" ) ) ) ) ) | BF10: =IF(AP10="","",ROUND(AR10/IF(BH10=1,127,IF(BH10=2,220,IF(BH10=3,381,""))),1)) | BG10: =(BF10*AX10)/(BD10*BA10) -> #VALUE! | BH10: =IF(COUNTA(BJ10:BL10)=0,"",COUNTA(BJ10:BL10)) | BI10: =IF(AP10="","", IF(COUNTA(V10:AE10)>=1, MAX(IFERROR(_xlfn.AGGREGATE(15,6,DISJUNTORES!$C$2:$C$100/(DISJUNTORES!$C$2:$C$100>=BF10),1),""),25), IF(COUNTA(L10:U10)>=1, MAX(IFERROR(_xlfn.AGGREGATE(15,6,DISJUNTORES!$C$2:$C$100/(DISJUNTORES!$C$2:$C$100>=BF10),1),""),20), IF(COUNTA(A10:K10)>=1, MAX(IFERROR(_xlfn.AGGREGATE(15,6,DISJUNTORES!$C$2:$C$100/(DISJUNTORES!$C$2:$C$100>=BF10),1),""),16), IFERROR(_xlfn.AGGREGATE(15,6,DISJUNTORES!$C$2:$C$100/(DISJUNTORES!$C$2:$C$100>=BF10),1),""))))) | BM10: =IF(IF(BJ10="","",AR10/COUNTA(BJ10:BL10))=0,"",IF(BJ10="","",AR10/COUNTA(BJ10:BL10))) | BN10: =IF(IF(BK10="","",AR10/COUNTA(BJ10:BL10))=0,"",IF(BK10="","",AR10/COUNTA(BJ10:BL10))) | BO10: =IF(IF(BL10="","",AR10/COUNTA(BJ10:BL10))=0,"",IF(BL10="","",AR10/COUNTA(BJ10:BL10))) | BP10: {=IFERROR( INDEX( IF(AV10="PVC", 'CAP CONDUÇÃO 70º'!$A:$A, 'CAP CONDUÇÃO 90º'!$A:$A), IF( COUNTIF( IF(AV10="PVC", CHOOSE( MATCH(AU10, {"A1 - 2";"A1 - 3";"A2 - 2";"A2 - 3";"B1 - 2";"B1 - 3";"B2 - 2";"B2 - 3";"C - 2";"C - 3";"D - 2";"D - 3";"E - 2";"E - 3";"F - 2";"F - 3TRI";"F - 3JUST";"G - 3HOR";"G - 3VER"}, 0), 'CAP CONDUÇÃO 70º'!$B:$B, 'CAP CONDUÇÃO 70º'!$C:$C, 'CAP CONDUÇÃO 70º'!$D:$D, 'CAP CONDUÇÃO 70º'!$E:$E, 'CAP CONDUÇÃO 70º'!$F:$F, 'CAP CONDUÇÃO 70º'!$G:$G, 'CAP CONDUÇÃO 70º'!$H:$H, 'CAP CONDUÇÃO 70º'!$I:$I, 'CAP CONDUÇÃO 70º'!$J:$J, 'CAP CONDUÇÃO 70º'!$K:$K, 'CAP CONDUÇÃO 70º'!$L:$L, 'CAP CONDUÇÃO 70º'!$M:$M, 'CAP CONDUÇÃO 70º'!$N:$N, 'CAP CONDUÇÃO 70º'!$O:$O, 'CAP CONDUÇÃO 70º'!$P:$P, 'CAP CONDUÇÃO 70º'!$Q:$Q, 'CAP CONDUÇÃO 70º'!$R:$R, 'CAP CONDUÇÃO 70º'!$S:$S, 'CAP CONDUÇÃO 70º'!$T:$T ), CHOOSE( MATCH(AU10, {"A1 - 2";"A1 - 3";"A2 - 2";"A2 - 3";"B1 - 2";"B1 - 3";"B2 - 2";"B2 - 3";"C - 2";"C - 3";"D - 2";"D - 3";"E - 2";"E - 3";"F - 2";"F - 3TRI";"F - 3JUST";"G - 3HOR";"G - 3VER"}, 0), 'CAP CONDUÇÃO 90º'!$B:$B, 'CAP CONDUÇÃO 90º'!$C:$C, 'CAP CONDUÇÃO 90º'!$D:$D, 'CAP CONDUÇÃO 90º'!$E:$E, 'CAP CONDUÇÃO 90º'!$F:$F, 'CAP CONDUÇÃO 90º'!$G:$G, 'CAP CONDUÇÃO 90º'!$H:$H, 'CAP CONDUÇÃO 90º'!$I:$I, 'CAP CONDUÇÃO 90º'!$J:$J, 'CAP CONDUÇÃO 90º'!$K:$K, 'CAP CONDUÇÃO 90º'!$L:$L, 'CAP CONDUÇÃO 90º'!$M:$M, 'CAP CONDUÇÃO 90º'!$N:$N, 'CAP CONDUÇÃO 90º'!$O:$O, 'CAP CONDUÇÃO 90º'!$P:$P, 'CAP CONDUÇÃO 90º'!$Q:$Q, 'CAP CONDUÇÃO 90º'!$R:$R, 'CAP CONDUÇÃO 90º'!$S:$S, 'CAP CONDUÇÃO 90º'!$T:$T ) ), BI10 ) > 0, MATCH(BI10, IF(AV10="PVC", CHOOSE( MATCH(AU10, {"A1 - 2";"A1 - 3";"A2 - 2";"A2 - 3";"B1 - 2";"B1 - 3";"B2 - 2";"B2 - 3";"C - 2";"C - 3";"D - 2";"D - 3";"E - 2";"E - 3";"F - 2";"F - 3TRI";"F - 3JUST";"G - 3HOR";"G - 3VER"}, 0), 'CAP CONDUÇÃO 70º'!$B:$B, 'CAP CONDUÇÃO 70º'!$C:$C, 'CAP CONDUÇÃO 70º'!$D:$D, 'CAP CONDUÇÃO 70º'!$E:$E, 'CAP CONDUÇÃO 70º'!$F:$F, 'CAP CONDUÇÃO 70º'!$G:$G, 'CAP CONDUÇÃO 70º'!$H:$H, 'CAP CONDUÇÃO 70º'!$I:$I, 'CAP CONDUÇÃO 70º'!$J:$J, 'CAP CONDUÇÃO 70º'!$K:$K, 'CAP CONDUÇÃO 70º'!$L:$L, 'CAP CONDUÇÃO 70º'!$M:$M, 'CAP CONDUÇÃO 70º'!$N:$N, 'CAP CONDUÇÃO 70º'!$O:$O, 'CAP CONDUÇÃO 70º'!$P:$P, 'CAP CONDUÇÃO 70º'!$Q:$Q, 'CAP CONDUÇÃO 70º'!$R:$R, 'CAP CONDUÇÃO 70º'!$S:$S, 'CAP CONDUÇÃO 70º'!$T:$T ), CHOOSE( MATCH(AU10, {"A1 - 2";"A1 - 3";"A2 - 2";"A2 - 3";"B1 - 2";"B1 - 3";"B2 - 2";"B2 - 3";"C - 2";"C - 3";"D - 2";"D - 3";"E - 2";"E - 3";"F - 2";"F - 3TRI";"F - 3JUST";"G - 3HOR";"G - 3VER"}, 0), 'CAP CONDUÇÃO 90º'!$B:$B, 'CAP CONDUÇÃO 90º'!$C:$C, 'CAP CONDUÇÃO 90º'!$D:$D, 'CAP CONDUÇÃO 90º'!$E:$E, 'CAP CONDUÇÃO 90º'!$F:$F, 'CAP CONDUÇÃO 90º'!$G:$G, 'CAP CONDUÇÃO 90º'!$H:$H, 'CAP CONDUÇÃO 90º'!$I:$I, 'CAP CONDUÇÃO 90º'!$J:$J, 'CAP CONDUÇÃO 90º'!$K:$K, 'CAP CONDUÇÃO 90º'!$L:$L, 'CAP CONDUÇÃO 90º'!$M:$M, 'CAP CONDUÇÃO 90º'!$N:$N, 'CAP CONDUÇÃO 90º'!$O:$O, 'CAP CONDUÇÃO 90º'!$P:$P, 'CAP CONDUÇÃO 90º'!$Q:$Q, 'CAP CONDUÇÃO 90º'!$R:$R, 'CAP CONDUÇÃO 90º'!$S:$S, 'CAP CONDUÇÃO 90º'!$T:$T ) ), 0 ), MATCH(BI10, IF(AV10="PVC", CHOOSE( MATCH(AU10, {"A1 - 2";"A1 - 3";"A2 - 2";"A2 - 3";"B1 - 2";"B1 - 3";"B2 - 2";"B2 - 3";"C - 2";"C - 3";"D - 2";"D - 3";"E - 2";"E - 3";"F - 2";"F - 3TRI";"F - 3JUST";"G - 3HOR";"G - 3VER"}, 0), 'CAP CONDUÇÃO 70º'!$B:$B, 'CAP CONDUÇÃO 70º'!$C:$C, 'CAP CONDUÇÃO 70º'!$D:$D, 'CAP CONDUÇÃO 70º'!$E:$E, 'CAP CONDUÇÃO 70º'!$F:$F, 'CAP CONDUÇÃO 70º'!$G:$G, 'CAP CONDUÇÃO 70º'!$H:$H, 'CAP CONDUÇÃO 70º'!$I:$I, 'CAP CONDUÇÃO 70º'!$J:$J, 'CAP CONDUÇÃO 70º'!$K:$K, 'CAP CONDUÇÃO 70º'!$L:$L, 'CAP CONDUÇÃO 70º'!$M:$M, 'CAP CONDUÇÃO 70º'!$N:$N, 'CAP CONDUÇÃO 70º'!$O:$O, 'CAP CONDUÇÃO 70º'!$P:$P, 'CAP CONDUÇÃO 70º'!$Q:$Q, 'CAP CONDUÇÃO 70º'!$R:$R, 'CAP CONDUÇÃO 70º'!$S:$S, 'CAP CONDUÇÃO 70º'!$T:$T ), CHOOSE( MATCH(AU10, {"A1 - 2";"A1 - 3";"A2 - 2";"A2 - 3";"B1 - 2";"B1 - 3";"B2 - 2";"B2 - 3";"C - 2";"C - 3";"D - 2";"D - 3";"E - 2";"E - 3";"F - 2";"F - 3TRI";"F - 3JUST";"G - 3HOR";"G - 3VER"}, 0), 'CAP CONDUÇÃO 90º'!$B:$B, 'CAP CONDUÇÃO 90º'!$C:$C, 'CAP CONDUÇÃO 90º'!$D:$D, 'CAP CONDUÇÃO 90º'!$E:$E, 'CAP CONDUÇÃO 90º'!$F:$F, 'CAP CONDUÇÃO 90º'!$G:$G, 'CAP CONDUÇÃO 90º'!$H:$H, 'CAP CONDUÇÃO 90º'!$I:$I, 'CAP CONDUÇÃO 90º'!$J:$J, 'CAP CONDUÇÃO 90º'!$K:$K, 'CAP CONDUÇÃO 90º'!$L:$L, 'CAP CONDUÇÃO 90º'!$M:$M, 'CAP CONDUÇÃO 90º'!$N:$N, 'CAP CONDUÇÃO 90º'!$O:$O, 'CAP CONDUÇÃO 90º'!$P:$P, 'CAP CONDUÇÃO 90º'!$Q:$Q, 'CAP CONDUÇÃO 90º'!$R:$R, 'CAP CONDUÇÃO 90º'!$S:$S, 'CAP CONDUÇÃO 90º'!$T:$T ) ), 1 ) + 1 ) ), "Não há valor maior ou igual" )} -> Não há valor maior ou igual | BS10: =IFERROR(IF(BP10="","","3F#"&BR10&"mm²+N"&VLOOKUP($BR$5,NEUTRO!$A:$B,2,0)&"mm²+T"&VLOOKUP($BR$5,TERRA!$A:$B,2,0)&"mm²"),"")
A11: 7 | AP11: =IF(SUMPRODUCT(B11:AO11, B$4:AO$4)=0, "", SUMPRODUCT(B11:AO11, B$4:AO$4)) | AQ11: =IF(AP11="","",IF((SUM(B11:K11)+SUM(AF11:AO11))>=1,1,0.92)) | AR11: =IF(AP11="","",ROUND((AP11/AQ11),0)) | AY11: Em feixe: ao ar livre ou sobre superfície; embutidos; em conduto fechado (métodos A a F) | AZ11: 1 | BA11: =INDEX(AGRUPAMENTO!C9:N13,MATCH(AY11,AGRUPAMENTO!B9:B13,0),MATCH(AZ11,AGRUPAMENTO!C8:N8,0)) -> #N/A | BB11: NÃO SUBTERRÂNEA | BC11: 30 | BD11: =IF(BB11="SUBTERRÂNEA",IF(AV11="PVC",VLOOKUP(BC11,TEMPERATURA!G8:H22,2,0),VLOOKUP(BC11,TEMPERATURA!G8:I22,3,0)),IF(AV11="PVC",VLOOKUP(BC11,TEMPERATURA!B8:C22,2,0),VLOOKUP(BC11,TEMPERATURA!B8:D22,3,0))) -> #N/A | BE11: =IF( AP11="", "", _xlfn.IFS( $BI$111="127/220", IF( BH11=1, 127, IF( BH11=2, ROUND(127*SQRT(3),0), IF( BH11=3, ROUND(127*SQRT(3),0), "" ) ) ), $BI$111="220/380", IF( BH11=1, 220, IF( BH11=2, ROUND(220*SQRT(3),0)-1, IF( BH11=3, ROUND(220*SQRT(3),0)-1, "" ) ) ), $BI$111="254/440", IF( BH11=1, 254, IF( BH11=2, ROUND(254*SQRT(3),0), IF( BH11=3, ROUND(254*SQRT(3),0), "" ) ) ) ) ) | BF11: =IF(AP11="","",ROUND(AR11/IF(BH11=1,127,IF(BH11=2,220,IF(BH11=3,381,""))),1)) | BG11: =(BF11*AX11)/(BD11*BA11) -> #VALUE! | BH11: =IF(COUNTA(BJ11:BL11)=0,"",COUNTA(BJ11:BL11)) | BI11: =IF(AP11="","", IF(COUNTA(V11:AE11)>=1, MAX(IFERROR(_xlfn.AGGREGATE(15,6,DISJUNTORES!$C$2:$C$100/(DISJUNTORES!$C$2:$C$100>=BF11),1),""),25), IF(COUNTA(L11:U11)>=1, MAX(IFERROR(_xlfn.AGGREGATE(15,6,DISJUNTORES!$C$2:$C$100/(DISJUNTORES!$C$2:$C$100>=BF11),1),""),20), IF(COUNTA(A11:K11)>=1, MAX(IFERROR(_xlfn.AGGREGATE(15,6,DISJUNTORES!$C$2:$C$100/(DISJUNTORES!$C$2:$C$100>=BF11),1),""),16), IFERROR(_xlfn.AGGREGATE(15,6,DISJUNTORES!$C$2:$C$100/(DISJUNTORES!$C$2:$C$100>=BF11),1),""))))) | BM11: =IF(IF(BJ11="","",AR11/COUNTA(BJ11:BL11))=0,"",IF(BJ11="","",AR11/COUNTA(BJ11:BL11))) | BN11: =IF(IF(BK11="","",AR11/COUNTA(BJ11:BL11))=0,"",IF(BK11="","",AR11/COUNTA(BJ11:BL11))) | BO11: =IF(IF(BL11="","",AR11/COUNTA(BJ11:BL11))=0,"",IF(BL11="","",AR11/COUNTA(BJ11:BL11))) | BP11: {=IFERROR( INDEX( IF(AV11="PVC", 'CAP CONDUÇÃO 70º'!$A:$A, 'CAP CONDUÇÃO 90º'!$A:$A), IF( COUNTIF( IF(AV11="PVC", CHOOSE( MATCH(AU11, {"A1 - 2";"A1 - 3";"A2 - 2";"A2 - 3";"B1 - 2";"B1 - 3";"B2 - 2";"B2 - 3";"C - 2";"C - 3";"D - 2";"D - 3";"E - 2";"E - 3";"F - 2";"F - 3TRI";"F - 3JUST";"G - 3HOR";"G - 3VER"}, 0), 'CAP CONDUÇÃO 70º'!$B:$B, 'CAP CONDUÇÃO 70º'!$C:$C, 'CAP CONDUÇÃO 70º'!$D:$D, 'CAP CONDUÇÃO 70º'!$E:$E, 'CAP CONDUÇÃO 70º'!$F:$F, 'CAP CONDUÇÃO 70º'!$G:$G, 'CAP CONDUÇÃO 70º'!$H:$H, 'CAP CONDUÇÃO 70º'!$I:$I, 'CAP CONDUÇÃO 70º'!$J:$J, 'CAP CONDUÇÃO 70º'!$K:$K, 'CAP CONDUÇÃO 70º'!$L:$L, 'CAP CONDUÇÃO 70º'!$M:$M, 'CAP CONDUÇÃO 70º'!$N:$N, 'CAP CONDUÇÃO 70º'!$O:$O, 'CAP CONDUÇÃO 70º'!$P:$P, 'CAP CONDUÇÃO 70º'!$Q:$Q, 'CAP CONDUÇÃO 70º'!$R:$R, 'CAP CONDUÇÃO 70º'!$S:$S, 'CAP CONDUÇÃO 70º'!$T:$T ), CHOOSE( MATCH(AU11, {"A1 - 2";"A1 - 3";"A2 - 2";"A2 - 3";"B1 - 2";"B1 - 3";"B2 - 2";"B2 - 3";"C - 2";"C - 3";"D - 2";"D - 3";"E - 2";"E - 3";"F - 2";"F - 3TRI";"F - 3JUST";"G - 3HOR";"G - 3VER"}, 0), 'CAP CONDUÇÃO 90º'!$B:$B, 'CAP CONDUÇÃO 90º'!$C:$C, 'CAP CONDUÇÃO 90º'!$D:$D, 'CAP CONDUÇÃO 90º'!$E:$E, 'CAP CONDUÇÃO 90º'!$F:$F, 'CAP CONDUÇÃO 90º'!$G:$G, 'CAP CONDUÇÃO 90º'!$H:$H, 'CAP CONDUÇÃO 90º'!$I:$I, 'CAP CONDUÇÃO 90º'!$J:$J, 'CAP CONDUÇÃO 90º'!$K:$K, 'CAP CONDUÇÃO 90º'!$L:$L, 'CAP CONDUÇÃO 90º'!$M:$M, 'CAP CONDUÇÃO 90º'!$N:$N, 'CAP CONDUÇÃO 90º'!$O:$O, 'CAP CONDUÇÃO 90º'!$P:$P, 'CAP CONDUÇÃO 90º'!$Q:$Q, 'CAP CONDUÇÃO 90º'!$R:$R, 'CAP CONDUÇÃO 90º'!$S:$S, 'CAP CONDUÇÃO 90º'!$T:$T ) ), BI11 ) > 0, MATCH(BI11, IF(AV11="PVC", CHOOSE( MATCH(AU11, {"A1 - 2";"A1 - 3";"A2 - 2";"A2 - 3";"B1 - 2";"B1 - 3";"B2 - 2";"B2 - 3";"C - 2";"C - 3";"D - 2";"D - 3";"E - 2";"E - 3";"F - 2";"F - 3TRI";"F - 3JUST";"G - 3HOR";"G - 3VER"}, 0), 'CAP CONDUÇÃO 70º'!$B:$B, 'CAP CONDUÇÃO 70º'!$C:$C, 'CAP CONDUÇÃO 70º'!$D:$D, 'CAP CONDUÇÃO 70º'!$E:$E, 'CAP CONDUÇÃO 70º'!$F:$F, 'CAP CONDUÇÃO 70º'!$G:$G, 'CAP CONDUÇÃO 70º'!$H:$H, 'CAP CONDUÇÃO 70º'!$I:$I, 'CAP CONDUÇÃO 70º'!$J:$J, 'CAP CONDUÇÃO 70º'!$K:$K, 'CAP CONDUÇÃO 70º'!$L:$L, 'CAP CONDUÇÃO 70º'!$M:$M, 'CAP CONDUÇÃO 70º'!$N:$N, 'CAP CONDUÇÃO 70º'!$O:$O, 'CAP CONDUÇÃO 70º'!$P:$P, 'CAP CONDUÇÃO 70º'!$Q:$Q, 'CAP CONDUÇÃO 70º'!$R:$R, 'CAP CONDUÇÃO 70º'!$S:$S, 'CAP CONDUÇÃO 70º'!$T:$T ), CHOOSE( MATCH(AU11, {"A1 - 2";"A1 - 3";"A2 - 2";"A2 - 3";"B1 - 2";"B1 - 3";"B2 - 2";"B2 - 3";"C - 2";"C - 3";"D - 2";"D - 3";"E - 2";"E - 3";"F - 2";"F - 3TRI";"F - 3JUST";"G - 3HOR";"G - 3VER"}, 0), 'CAP CONDUÇÃO 90º'!$B:$B, 'CAP CONDUÇÃO 90º'!$C:$C, 'CAP CONDUÇÃO 90º'!$D:$D, 'CAP CONDUÇÃO 90º'!$E:$E, 'CAP CONDUÇÃO 90º'!$F:$F, 'CAP CONDUÇÃO 90º'!$G:$G, 'CAP CONDUÇÃO 90º'!$H:$H, 'CAP CONDUÇÃO 90º'!$I:$I, 'CAP CONDUÇÃO 90º'!$J:$J, 'CAP CONDUÇÃO 90º'!$K:$K, 'CAP CONDUÇÃO 90º'!$L:$L, 'CAP CONDUÇÃO 90º'!$M:$M, 'CAP CONDUÇÃO 90º'!$N:$N, 'CAP CONDUÇÃO 90º'!$O:$O, 'CAP CONDUÇÃO 90º'!$P:$P, 'CAP CONDUÇÃO 90º'!$Q:$Q, 'CAP CONDUÇÃO 90º'!$R:$R, 'CAP CONDUÇÃO 90º'!$S:$S, 'CAP CONDUÇÃO 90º'!$T:$T ) ), 0 ), MATCH(BI11, IF(AV11="PVC", CHOOSE( MATCH(AU11, {"A1 - 2";"A1 - 3";"A2 - 2";"A2 - 3";"B1 - 2";"B1 - 3";"B2 - 2";"B2 - 3";"C - 2";"C - 3";"D - 2";"D - 3";"E - 2";"E - 3";"F - 2";"F - 3TRI";"F - 3JUST";"G - 3HOR";"G - 3VER"}, 0), 'CAP CONDUÇÃO 70º'!$B:$B, 'CAP CONDUÇÃO 70º'!$C:$C, 'CAP CONDUÇÃO 70º'!$D:$D, 'CAP CONDUÇÃO 70º'!$E:$E, 'CAP CONDUÇÃO 70º'!$F:$F, 'CAP CONDUÇÃO 70º'!$G:$G, 'CAP CONDUÇÃO 70º'!$H:$H, 'CAP CONDUÇÃO 70º'!$I:$I, 'CAP CONDUÇÃO 70º'!$J:$J, 'CAP CONDUÇÃO 70º'!$K:$K, 'CAP CONDUÇÃO 70º'!$L:$L, 'CAP CONDUÇÃO 70º'!$M:$M, 'CAP CONDUÇÃO 70º'!$N:$N, 'CAP CONDUÇÃO 70º'!$O:$O, 'CAP CONDUÇÃO 70º'!$P:$P, 'CAP CONDUÇÃO 70º'!$Q:$Q, 'CAP CONDUÇÃO 70º'!$R:$R, 'CAP CONDUÇÃO 70º'!$S:$S, 'CAP CONDUÇÃO 70º'!$T:$T ), CHOOSE( MATCH(AU11, {"A1 - 2";"A1 - 3";"A2 - 2";"A2 - 3";"B1 - 2";"B1 - 3";"B2 - 2";"B2 - 3";"C - 2";"C - 3";"D - 2";"D - 3";"E - 2";"E - 3";"F - 2";"F - 3TRI";"F - 3JUST";"G - 3HOR";"G - 3VER"}, 0), 'CAP CONDUÇÃO 90º'!$B:$B, 'CAP CONDUÇÃO 90º'!$C:$C, 'CAP CONDUÇÃO 90º'!$D:$D, 'CAP CONDUÇÃO 90º'!$E:$E, 'CAP CONDUÇÃO 90º'!$F:$F, 'CAP CONDUÇÃO 90º'!$G:$G, 'CAP CONDUÇÃO 90º'!$H:$H, 'CAP CONDUÇÃO 90º'!$I:$I, 'CAP CONDUÇÃO 90º'!$J:$J, 'CAP CONDUÇÃO 90º'!$K:$K, 'CAP CONDUÇÃO 90º'!$L:$L, 'CAP CONDUÇÃO 90º'!$M:$M, 'CAP CONDUÇÃO 90º'!$N:$N, 'CAP CONDUÇÃO 90º'!$O:$O, 'CAP CONDUÇÃO 90º'!$P:$P, 'CAP CONDUÇÃO 90º'!$Q:$Q, 'CAP CONDUÇÃO 90º'!$R:$R, 'CAP CONDUÇÃO 90º'!$S:$S, 'CAP CONDUÇÃO 90º'!$T:$T ) ), 1 ) + 1 ) ), "Não há valor maior ou igual" )} -> Não há valor maior ou igual | BS11: =IFERROR(IF(BP11="","","3F#"&BR11&"mm²+N"&VLOOKUP($BR$5,NEUTRO!$A:$B,2,0)&"mm²+T"&VLOOKUP($BR$5,TERRA!$A:$B,2,0)&"mm²"),"")
A12: 8 | AP12: =IF(SUMPRODUCT(B12:AO12, B$4:AO$4)=0, "", SUMPRODUCT(B12:AO12, B$4:AO$4)) | AQ12: =IF(AP12="","",IF((SUM(B12:K12)+SUM(AF12:AO12))>=1,1,0.92)) | AR12: =IF(AP12="","",ROUND((AP12/AQ12),0)) | AY12: Em feixe: ao ar livre ou sobre superfície; embutidos; em conduto fechado (métodos A a F) | AZ12: 1 | BA12: =INDEX(AGRUPAMENTO!C10:N14,MATCH(AY12,AGRUPAMENTO!B10:B14,0),MATCH(AZ12,AGRUPAMENTO!C9:N9,0)) -> #N/A | BB12: NÃO SUBTERRÂNEA | BC12: 30 | BD12: =IF(BB12="SUBTERRÂNEA",IF(AV12="PVC",VLOOKUP(BC12,TEMPERATURA!G9:H23,2,0),VLOOKUP(BC12,TEMPERATURA!G9:I23,3,0)),IF(AV12="PVC",VLOOKUP(BC12,TEMPERATURA!B9:C23,2,0),VLOOKUP(BC12,TEMPERATURA!B9:D23,3,0))) -> #N/A | BE12: =IF( AP12="", "", _xlfn.IFS( $BI$111="127/220", IF( BH12=1, 127, IF( BH12=2, ROUND(127*SQRT(3),0), IF( BH12=3, ROUND(127*SQRT(3),0), "" ) ) ), $BI$111="220/380", IF( BH12=1, 220, IF( BH12=2, ROUND(220*SQRT(3),0)-1, IF( BH12=3, ROUND(220*SQRT(3),0)-1, "" ) ) ), $BI$111="254/440", IF( BH12=1, 254, IF( BH12=2, ROUND(254*SQRT(3),0), IF( BH12=3, ROUND(254*SQRT(3),0), "" ) ) ) ) ) | BF12: =IF(AP12="","",ROUND(AR12/IF(BH12=1,127,IF(BH12=2,220,IF(BH12=3,381,""))),1)) | BG12: =(BF12*AX12)/(BD12*BA12) -> #VALUE! | BH12: =IF(COUNTA(BJ12:BL12)=0,"",COUNTA(BJ12:BL12)) | BI12: =IF(AP12="","", IF(COUNTA(V12:AE12)>=1, MAX(IFERROR(_xlfn.AGGREGATE(15,6,DISJUNTORES!$C$2:$C$100/(DISJUNTORES!$C$2:$C$100>=BF12),1),""),25), IF(COUNTA(L12:U12)>=1, MAX(IFERROR(_xlfn.AGGREGATE(15,6,DISJUNTORES!$C$2:$C$100/(DISJUNTORES!$C$2:$C$100>=BF12),1),""),20), IF(COUNTA(A12:K12)>=1, MAX(IFERROR(_xlfn.AGGREGATE(15,6,DISJUNTORES!$C$2:$C$100/(DISJUNTORES!$C$2:$C$100>=BF12),1),""),16), IFERROR(_xlfn.AGGREGATE(15,6,DISJUNTORES!$C$2:$C$100/(DISJUNTORES!$C$2:$C$100>=BF12),1),""))))) | BM12: =IF(IF(BJ12="","",AR12/COUNTA(BJ12:BL12))=0,"",IF(BJ12="","",AR12/COUNTA(BJ12:BL12))) | BN12: =IF(IF(BK12="","",AR12/COUNTA(BJ12:BL12))=0,"",IF(BK12="","",AR12/COUNTA(BJ12:BL12))) | BO12: =IF(IF(BL12="","",AR12/COUNTA(BJ12:BL12))=0,"",IF(BL12="","",AR12/COUNTA(BJ12:BL12))) | BP12: {=IFERROR( INDEX( IF(AV12="PVC", 'CAP CONDUÇÃO 70º'!$A:$A, 'CAP CONDUÇÃO 90º'!$A:$A), IF( COUNTIF( IF(AV12="PVC", CHOOSE( MATCH(AU12, {"A1 - 2";"A1 - 3";"A2 - 2";"A2 - 3";"B1 - 2";"B1 - 3";"B2 - 2";"B2 - 3";"C - 2";"C - 3";"D - 2";"D - 3";"E - 2";"E - 3";"F - 2";"F - 3TRI";"F - 3JUST";"G - 3HOR";"G - 3VER"}, 0), 'CAP CONDUÇÃO 70º'!$B:$B, 'CAP CONDUÇÃO 70º'!$C:$C, 'CAP CONDUÇÃO 70º'!$D:$D, 'CAP CONDUÇÃO 70º'!$E:$E, 'CAP CONDUÇÃO 70º'!$F:$F, 'CAP CONDUÇÃO 70º'!$G:$G, 'CAP CONDUÇÃO 70º'!$H:$H, 'CAP CONDUÇÃO 70º'!$I:$I, 'CAP CONDUÇÃO 70º'!$J:$J, 'CAP CONDUÇÃO 70º'!$K:$K, 'CAP CONDUÇÃO 70º'!$L:$L, 'CAP CONDUÇÃO 70º'!$M:$M, 'CAP CONDUÇÃO 70º'!$N:$N, 'CAP CONDUÇÃO 70º'!$O:$O, 'CAP CONDUÇÃO 70º'!$P:$P, 'CAP CONDUÇÃO 70º'!$Q:$Q, 'CAP CONDUÇÃO 70º'!$R:$R, 'CAP CONDUÇÃO 70º'!$S:$S, 'CAP CONDUÇÃO 70º'!$T:$T ), CHOOSE( MATCH(AU12, {"A1 - 2";"A1 - 3";"A2 - 2";"A2 - 3";"B1 - 2";"B1 - 3";"B2 - 2";"B2 - 3";"C - 2";"C - 3";"D - 2";"D - 3";"E - 2";"E - 3";"F - 2";"F - 3TRI";"F - 3JUST";"G - 3HOR";"G - 3VER"}, 0), 'CAP CONDUÇÃO 90º'!$B:$B, 'CAP CONDUÇÃO 90º'!$C:$C, 'CAP CONDUÇÃO 90º'!$D:$D, 'CAP CONDUÇÃO 90º'!$E:$E, 'CAP CONDUÇÃO 90º'!$F:$F, 'CAP CONDUÇÃO 90º'!$G:$G, 'CAP CONDUÇÃO 90º'!$H:$H, 'CAP CONDUÇÃO 90º'!$I:$I, 'CAP CONDUÇÃO 90º'!$J:$J, 'CAP CONDUÇÃO 90º'!$K:$K, 'CAP CONDUÇÃO 90º'!$L:$L, 'CAP CONDUÇÃO 90º'!$M:$M, 'CAP CONDUÇÃO 90º'!$N:$N, 'CAP CONDUÇÃO 90º'!$O:$O, 'CAP CONDUÇÃO 90º'!$P:$P, 'CAP CONDUÇÃO 90º'!$Q:$Q, 'CAP CONDUÇÃO 90º'!$R:$R, 'CAP CONDUÇÃO 90º'!$S:$S, 'CAP CONDUÇÃO 90º'!$T:$T ) ), BI12 ) > 0, MATCH(BI12, IF(AV12="PVC", CHOOSE( MATCH(AU12, {"A1 - 2";"A1 - 3";"A2 - 2";"A2 - 3";"B1 - 2";"B1 - 3";"B2 - 2";"B2 - 3";"C - 2";"C - 3";"D - 2";"D - 3";"E - 2";"E - 3";"F - 2";"F - 3TRI";"F - 3JUST";"G - 3HOR";"G - 3VER"}, 0), 'CAP CONDUÇÃO 70º'!$B:$B, 'CAP CONDUÇÃO 70º'!$C:$C, 'CAP CONDUÇÃO 70º'!$D:$D, 'CAP CONDUÇÃO 70º'!$E:$E, 'CAP CONDUÇÃO 70º'!$F:$F, 'CAP CONDUÇÃO 70º'!$G:$G, 'CAP CONDUÇÃO 70º'!$H:$H, 'CAP CONDUÇÃO 70º'!$I:$I, 'CAP CONDUÇÃO 70º'!$J:$J, 'CAP CONDUÇÃO 70º'!$K:$K, 'CAP CONDUÇÃO 70º'!$L:$L, 'CAP CONDUÇÃO 70º'!$M:$M, 'CAP CONDUÇÃO 70º'!$N:$N, 'CAP CONDUÇÃO 70º'!$O:$O, 'CAP CONDUÇÃO 70º'!$P:$P, 'CAP CONDUÇÃO 70º'!$Q:$Q, 'CAP CONDUÇÃO 70º'!$R:$R, 'CAP CONDUÇÃO 70º'!$S:$S, 'CAP CONDUÇÃO 70º'!$T:$T ), CHOOSE( MATCH(AU12, {"A1 - 2";"A1 - 3";"A2 - 2";"A2 - 3";"B1 - 2";"B1 - 3";"B2 - 2";"B2 - 3";"C - 2";"C - 3";"D - 2";"D - 3";"E - 2";"E - 3";"F - 2";"F - 3TRI";"F - 3JUST";"G - 3HOR";"G - 3VER"}, 0), 'CAP CONDUÇÃO 90º'!$B:$B, 'CAP CONDUÇÃO 90º'!$C:$C, 'CAP CONDUÇÃO 90º'!$D:$D, 'CAP CONDUÇÃO 90º'!$E:$E, 'CAP CONDUÇÃO 90º'!$F:$F, 'CAP CONDUÇÃO 90º'!$G:$G, 'CAP CONDUÇÃO 90º'!$H:$H, 'CAP CONDUÇÃO 90º'!$I:$I, 'CAP CONDUÇÃO 90º'!$J:$J, 'CAP CONDUÇÃO 90º'!$K:$K, 'CAP CONDUÇÃO 90º'!$L:$L, 'CAP CONDUÇÃO 90º'!$M:$M, 'CAP CONDUÇÃO 90º'!$N:$N, 'CAP CONDUÇÃO 90º'!$O:$O, 'CAP CONDUÇÃO 90º'!$P:$P, 'CAP CONDUÇÃO 90º'!$Q:$Q, 'CAP CONDUÇÃO 90º'!$R:$R, 'CAP CONDUÇÃO 90º'!$S:$S, 'CAP CONDUÇÃO 90º'!$T:$T ) ), 0 ), MATCH(BI12, IF(AV12="PVC", CHOOSE( MATCH(AU12, {"A1 - 2";"A1 - 3";"A2 - 2";"A2 - 3";"B1 - 2";"B1 - 3";"B2 - 2";"B2 - 3";"C - 2";"C - 3";"D - 2";"D - 3";"E - 2";"E - 3";"F - 2";"F - 3TRI";"F - 3JUST";"G - 3HOR";"G - 3VER"}, 0), 'CAP CONDUÇÃO 70º'!$B:$B, 'CAP CONDUÇÃO 70º'!$C:$C, 'CAP CONDUÇÃO 70º'!$D:$D, 'CAP CONDUÇÃO 70º'!$E:$E, 'CAP CONDUÇÃO 70º'!$F:$F, 'CAP CONDUÇÃO 70º'!$G:$G, 'CAP CONDUÇÃO 70º'!$H:$H, 'CAP CONDUÇÃO 70º'!$I:$I, 'CAP CONDUÇÃO 70º'!$J:$J, 'CAP CONDUÇÃO 70º'!$K:$K, 'CAP CONDUÇÃO 70º'!$L:$L, 'CAP CONDUÇÃO 70º'!$M:$M, 'CAP CONDUÇÃO 70º'!$N:$N, 'CAP CONDUÇÃO 70º'!$O:$O, 'CAP CONDUÇÃO 70º'!$P:$P, 'CAP CONDUÇÃO 70º'!$Q:$Q, 'CAP CONDUÇÃO 70º'!$R:$R, 'CAP CONDUÇÃO 70º'!$S:$S, 'CAP CONDUÇÃO 70º'!$T:$T ), CHOOSE( MATCH(AU12, {"A1 - 2";"A1 - 3";"A2 - 2";"A2 - 3";"B1 - 2";"B1 - 3";"B2 - 2";"B2 - 3";"C - 2";"C - 3";"D - 2";"D - 3";"E - 2";"E - 3";"F - 2";"F - 3TRI";"F - 3JUST";"G - 3HOR";"G - 3VER"}, 0), 'CAP CONDUÇÃO 90º'!$B:$B, 'CAP CONDUÇÃO 90º'!$C:$C, 'CAP CONDUÇÃO 90º'!$D:$D, 'CAP CONDUÇÃO 90º'!$E:$E, 'CAP CONDUÇÃO 90º'!$F:$F, 'CAP CONDUÇÃO 90º'!$G:$G, 'CAP CONDUÇÃO 90º'!$H:$H, 'CAP CONDUÇÃO 90º'!$I:$I, 'CAP CONDUÇÃO 90º'!$J:$J, 'CAP CONDUÇÃO 90º'!$K:$K, 'CAP CONDUÇÃO 90º'!$L:$L, 'CAP CONDUÇÃO 90º'!$M:$M, 'CAP CONDUÇÃO 90º'!$N:$N, 'CAP CONDUÇÃO 90º'!$O:$O, 'CAP CONDUÇÃO 90º'!$P:$P, 'CAP CONDUÇÃO 90º'!$Q:$Q, 'CAP CONDUÇÃO 90º'!$R:$R, 'CAP CONDUÇÃO 90º'!$S:$S, 'CAP CONDUÇÃO 90º'!$T:$T ) ), 1 ) + 1 ) ), "Não há valor maior ou igual" )} -> Não há valor maior ou igual | BS12: =IFERROR(IF(BP12="","","3F#"&BR12&"mm²+N"&VLOOKUP($BR$5,NEUTRO!$A:$B,2,0)&"mm²+T"&VLOOKUP($BR$5,TERRA!$A:$B,2,0)&"mm²"),"")
A13: 9 | AP13: =IF(SUMPRODUCT(B13:AO13, B$4:AO$4)=0, "", SUMPRODUCT(B13:AO13, B$4:AO$4)) | AQ13: =IF(AP13="","",IF((SUM(B13:K13)+SUM(AF13:AO13))>=1,1,0.92)) | AR13: =IF(AP13="","",ROUND((AP13/AQ13),0)) | AY13: Em feixe: ao ar livre ou sobre superfície; embutidos; em conduto fechado (métodos A a F) | AZ13: 1 | BA13: =INDEX(AGRUPAMENTO!C11:N15,MATCH(AY13,AGRUPAMENTO!B11:B15,0),MATCH(AZ13,AGRUPAMENTO!C10:N10,0)) -> #N/A | BB13: NÃO SUBTERRÂNEA | BC13: 30 | BD13: =IF(BB13="SUBTERRÂNEA",IF(AV13="PVC",VLOOKUP(BC13,TEMPERATURA!G10:H24,2,0),VLOOKUP(BC13,TEMPERATURA!G10:I24,3,0)),IF(AV13="PVC",VLOOKUP(BC13,TEMPERATURA!B10:C24,2,0),VLOOKUP(BC13,TEMPERATURA!B10:D24,3,0))) -> #N/A | BE13: =IF( AP13="", "", _xlfn.IFS( $BI$111="127/220", IF( BH13=1, 127, IF( BH13=2, ROUND(127*SQRT(3),0), IF( BH13=3, ROUND(127*SQRT(3),0), "" ) ) ), $BI$111="220/380", IF( BH13=1, 220, IF( BH13=2, ROUND(220*SQRT(3),0)-1, IF( BH13=3, ROUND(220*SQRT(3),0)-1, "" ) ) ), $BI$111="254/440", IF( BH13=1, 254, IF( BH13=2, ROUND(254*SQRT(3),0), IF( BH13=3, ROUND(254*SQRT(3),0), "" ) ) ) ) ) | BF13: =IF(AP13="","",ROUND(AR13/IF(BH13=1,127,IF(BH13=2,220,IF(BH13=3,381,""))),1)) | BG13: =(BF13*AX13)/(BD13*BA13) -> #VALUE! | BH13: =IF(COUNTA(BJ13:BL13)=0,"",COUNTA(BJ13:BL13)) | BI13: =IF(AP13="","", IF(COUNTA(V13:AE13)>=1, MAX(IFERROR(_xlfn.AGGREGATE(15,6,DISJUNTORES!$C$2:$C$100/(DISJUNTORES!$C$2:$C$100>=BF13),1),""),25), IF(COUNTA(L13:U13)>=1, MAX(IFERROR(_xlfn.AGGREGATE(15,6,DISJUNTORES!$C$2:$C$100/(DISJUNTORES!$C$2:$C$100>=BF13),1),""),20), IF(COUNTA(A13:K13)>=1, MAX(IFERROR(_xlfn.AGGREGATE(15,6,DISJUNTORES!$C$2:$C$100/(DISJUNTORES!$C$2:$C$100>=BF13),1),""),16), IFERROR(_xlfn.AGGREGATE(15,6,DISJUNTORES!$C$2:$C$100/(DISJUNTORES!$C$2:$C$100>=BF13),1),""))))) | BM13: =IF(IF(BJ13="","",AR13/COUNTA(BJ13:BL13))=0,"",IF(BJ13="","",AR13/COUNTA(BJ13:BL13))) | BN13: =IF(IF(BK13="","",AR13/COUNTA(BJ13:BL13))=0,"",IF(BK13="","",AR13/COUNTA(BJ13:BL13))) | BO13: =IF(IF(BL13="","",AR13/COUNTA(BJ13:BL13))=0,"",IF(BL13="","",AR13/COUNTA(BJ13:BL13))) | BP13: {=IFERROR( INDEX( IF(AV13="PVC", 'CAP CONDUÇÃO 70º'!$A:$A, 'CAP CONDUÇÃO 90º'!$A:$A), IF( COUNTIF( IF(AV13="PVC", CHOOSE( MATCH(AU13, {"A1 - 2";"A1 - 3";"A2 - 2";"A2 - 3";"B1 - 2";"B1 - 3";"B2 - 2";"B2 - 3";"C - 2";"C - 3";"D - 2";"D - 3";"E - 2";"E - 3";"F - 2";"F - 3TRI";"F - 3JUST";"G - 3HOR";"G - 3VER"}, 0), 'CAP CONDUÇÃO 70º'!$B:$B, 'CAP CONDUÇÃO 70º'!$C:$C, 'CAP CONDUÇÃO 70º'!$D:$D, 'CAP CONDUÇÃO 70º'!$E:$E, 'CAP CONDUÇÃO 70º'!$F:$F, 'CAP CONDUÇÃO 70º'!$G:$G, 'CAP CONDUÇÃO 70º'!$H:$H, 'CAP CONDUÇÃO 70º'!$I:$I, 'CAP CONDUÇÃO 70º'!$J:$J, 'CAP CONDUÇÃO 70º'!$K:$K, 'CAP CONDUÇÃO 70º'!$L:$L, 'CAP CONDUÇÃO 70º'!$M:$M, 'CAP CONDUÇÃO 70º'!$N:$N, 'CAP CONDUÇÃO 70º'!$O:$O, 'CAP CONDUÇÃO 70º'!$P:$P, 'CAP CONDUÇÃO 70º'!$Q:$Q, 'CAP CONDUÇÃO 70º'!$R:$R, 'CAP CONDUÇÃO 70º'!$S:$S, 'CAP CONDUÇÃO 70º'!$T:$T ), CHOOSE( MATCH(AU13, {"A1 - 2";"A1 - 3";"A2 - 2";"A2 - 3";"B1 - 2";"B1 - 3";"B2 - 2";"B2 - 3";"C - 2";"C - 3";"D - 2";"D - 3";"E - 2";"E - 3";"F - 2";"F - 3TRI";"F - 3JUST";"G - 3HOR";"G - 3VER"}, 0), 'CAP CONDUÇÃO 90º'!$B:$B, 'CAP CONDUÇÃO 90º'!$C:$C, 'CAP CONDUÇÃO 90º'!$D:$D, 'CAP CONDUÇÃO 90º'!$E:$E, 'CAP CONDUÇÃO 90º'!$F:$F, 'CAP CONDUÇÃO 90º'!$G:$G, 'CAP CONDUÇÃO 90º'!$H:$H, 'CAP CONDUÇÃO 90º'!$I:$I, 'CAP CONDUÇÃO 90º'!$J:$J, 'CAP CONDUÇÃO 90º'!$K:$K, 'CAP CONDUÇÃO 90º'!$L:$L, 'CAP CONDUÇÃO 90º'!$M:$M, 'CAP CONDUÇÃO 90º'!$N:$N, 'CAP CONDUÇÃO 90º'!$O:$O, 'CAP CONDUÇÃO 90º'!$P:$P, 'CAP CONDUÇÃO 90º'!$Q:$Q, 'CAP CONDUÇÃO 90º'!$R:$R, 'CAP CONDUÇÃO 90º'!$S:$S, 'CAP CONDUÇÃO 90º'!$T:$T ) ), BI13 ) > 0, MATCH(BI13, IF(AV13="PVC", CHOOSE( MATCH(AU13, {"A1 - 2";"A1 - 3";"A2 - 2";"A2 - 3";"B1 - 2";"B1 - 3";"B2 - 2";"B2 - 3";"C - 2";"C - 3";"D - 2";"D - 3";"E - 2";"E - 3";"F - 2";"F - 3TRI";"F - 3JUST";"G - 3HOR";"G - 3VER"}, 0), 'CAP CONDUÇÃO 70º'!$B:$B, 'CAP CONDUÇÃO 70º'!$C:$C, 'CAP CONDUÇÃO 70º'!$D:$D, 'CAP CONDUÇÃO 70º'!$E:$E, 'CAP CONDUÇÃO 70º'!$F:$F, 'CAP CONDUÇÃO 70º'!$G:$G, 'CAP CONDUÇÃO 70º'!$H:$H, 'CAP CONDUÇÃO 70º'!$I:$I, 'CAP CONDUÇÃO 70º'!$J:$J, 'CAP CONDUÇÃO 70º'!$K:$K, 'CAP CONDUÇÃO 70º'!$L:$L, 'CAP CONDUÇÃO 70º'!$M:$M, 'CAP CONDUÇÃO 70º'!$N:$N, 'CAP CONDUÇÃO 70º'!$O:$O, 'CAP CONDUÇÃO 70º'!$P:$P, 'CAP CONDUÇÃO 70º'!$Q:$Q, 'CAP CONDUÇÃO 70º'!$R:$R, 'CAP CONDUÇÃO 70º'!$S:$S, 'CAP CONDUÇÃO 70º'!$T:$T ), CHOOSE( MATCH(AU13, {"A1 - 2";"A1 - 3";"A2 - 2";"A2 - 3";"B1 - 2";"B1 - 3";"B2 - 2";"B2 - 3";"C - 2";"C - 3";"D - 2";"D - 3";"E - 2";"E - 3";"F - 2";"F - 3TRI";"F - 3JUST";"G - 3HOR";"G - 3VER"}, 0), 'CAP CONDUÇÃO 90º'!$B:$B, 'CAP CONDUÇÃO 90º'!$C:$C, 'CAP CONDUÇÃO 90º'!$D:$D, 'CAP CONDUÇÃO 90º'!$E:$E, 'CAP CONDUÇÃO 90º'!$F:$F, 'CAP CONDUÇÃO 90º'!$G:$G, 'CAP CONDUÇÃO 90º'!$H:$H, 'CAP CONDUÇÃO 90º'!$I:$I, 'CAP CONDUÇÃO 90º'!$J:$J, 'CAP CONDUÇÃO 90º'!$K:$K, 'CAP CONDUÇÃO 90º'!$L:$L, 'CAP CONDUÇÃO 90º'!$M:$M, 'CAP CONDUÇÃO 90º'!$N:$N, 'CAP CONDUÇÃO 90º'!$O:$O, 'CAP CONDUÇÃO 90º'!$P:$P, 'CAP CONDUÇÃO 90º'!$Q:$Q, 'CAP CONDUÇÃO 90º'!$R:$R, 'CAP CONDUÇÃO 90º'!$S:$S, 'CAP CONDUÇÃO 90º'!$T:$T ) ), 0 ), MATCH(BI13, IF(AV13="PVC", CHOOSE( MATCH(AU13, {"A1 - 2";"A1 - 3";"A2 - 2";"A2 - 3";"B1 - 2";"B1 - 3";"B2 - 2";"B2 - 3";"C - 2";"C - 3";"D - 2";"D - 3";"E - 2";"E - 3";"F - 2";"F - 3TRI";"F - 3JUST";"G - 3HOR";"G - 3VER"}, 0), 'CAP CONDUÇÃO 70º'!$B:$B, 'CAP CONDUÇÃO 70º'!$C:$C, 'CAP CONDUÇÃO 70º'!$D:$D, 'CAP CONDUÇÃO 70º'!$E:$E, 'CAP CONDUÇÃO 70º'!$F:$F, 'CAP CONDUÇÃO 70º'!$G:$G, 'CAP CONDUÇÃO 70º'!$H:$H, 'CAP CONDUÇÃO 70º'!$I:$I, 'CAP CONDUÇÃO 70º'!$J:$J, 'CAP CONDUÇÃO 70º'!$K:$K, 'CAP CONDUÇÃO 70º'!$L:$L, 'CAP CONDUÇÃO 70º'!$M:$M, 'CAP CONDUÇÃO 70º'!$N:$N, 'CAP CONDUÇÃO 70º'!$O:$O, 'CAP CONDUÇÃO 70º'!$P:$P, 'CAP CONDUÇÃO 70º'!$Q:$Q, 'CAP CONDUÇÃO 70º'!$R:$R, 'CAP CONDUÇÃO 70º'!$S:$S, 'CAP CONDUÇÃO 70º'!$T:$T ), CHOOSE( MATCH(AU13, {"A1 - 2";"A1 - 3";"A2 - 2";"A2 - 3";"B1 - 2";"B1 - 3";"B2 - 2";"B2 - 3";"C - 2";"C - 3";"D - 2";"D - 3";"E - 2";"E - 3";"F - 2";"F - 3TRI";"F - 3JUST";"G - 3HOR";"G - 3VER"}, 0), 'CAP CONDUÇÃO 90º'!$B:$B, 'CAP CONDUÇÃO 90º'!$C:$C, 'CAP CONDUÇÃO 90º'!$D:$D, 'CAP CONDUÇÃO 90º'!$E:$E, 'CAP CONDUÇÃO 90º'!$F:$F, 'CAP CONDUÇÃO 90º'!$G:$G, 'CAP CONDUÇÃO 90º'!$H:$H, 'CAP CONDUÇÃO 90º'!$I:$I, 'CAP CONDUÇÃO 90º'!$J:$J, 'CAP CONDUÇÃO 90º'!$K:$K, 'CAP CONDUÇÃO 90º'!$L:$L, 'CAP CONDUÇÃO 90º'!$M:$M, 'CAP CONDUÇÃO 90º'!$N:$N, 'CAP CONDUÇÃO 90º'!$O:$O, 'CAP CONDUÇÃO 90º'!$P:$P, 'CAP CONDUÇÃO 90º'!$Q:$Q, 'CAP CONDUÇÃO 90º'!$R:$R, 'CAP CONDUÇÃO 90º'!$S:$S, 'CAP CONDUÇÃO 90º'!$T:$T ) ), 1 ) + 1 ) ), "Não há valor maior ou igual" )} -> Não há valor maior ou igual | BS13: =IFERROR(IF(BP13="","","3F#"&BR13&"mm²+N"&VLOOKUP($BR$5,NEUTRO!$A:$B,2,0)&"mm²+T"&VLOOKUP($BR$5,TERRA!$A:$B,2,0)&"mm²"),"")
